Workbook

Sheet Pattern
A1: Cat. | B1: Categoria | C1: Resoconto (cosa dicono i dati) | D1: Fatti a supporto | E1: Solidità dell'evidenza | F1: Limiti: cosa NON possiamo dedurre | G1: Spunti per il design (ipotesi da verificare) | H1: N. fatti
A2: C1 | B2: Abitudini online e contatti con sconosciuti | C2: Scrivono soprattutto su WhatsApp, Instagram e TikTok. La maggior parte ha il profilo privato, spesso per scelta propria. I messaggi da sconosciuti sono frequenti, ma le studentesse intervistate dicono di scrivere quasi solo con persone che conoscono. | D2: Q02, Q03, Q04, Q05, S01–S04, S06, S07 | E2: Alta (questionario + intervista) | F2: Questionario quasi tutto maschile; per le chat dei videogiochi e Discord non ci sono dati qualitativi. | G2: Quali canali coprire per primi (WhatsApp, Instagram, TikTok)? Le chat dei videogiochi meritano un approfondimento? | H2: =COUNTIF(Fatti!$G:$G,A2) -> 6
A3: C2 | B3: Come valutano se un profilo è affidabile | C3: Il criterio principale è sociale: amici in comune, chi lo segue, "lo conoscono le mie amiche". Poi vengono segnali superficiali (numero di follower, foto profilo, aspetto) usati in modo incoerente: per alcuni pochi follower sono un segnale di falso, per altri anche 600 lo sono. Qualcuno usa strategie più evolute (età dell'account, ricerca dell'immagine, prefisso estero). | D3: Q06, Q07, Q22, S05, S08–S14 | E3: Alta (questionario + intervista + esercizio) | F3: La codifica della domanda aperta è per parole chiave: va controllata a mano (foglio "Q aperta codificata"). Un solo esercizio con due profili. | G3: Ipotesi: insegnare che gli "amici in comune" e i follower non bastano come garanzia; allenare a segnali più affidabili (età dell'account, ricerca inversa dell'immagine, comportamento in chat). | H3: =COUNTIF(Fatti!$G:$G,A3) -> 8
A4: C3 | B4: Fiducia nelle proprie capacità vs comportamenti reali | C4: Circa 3 su 4 si sentono capaci di accorgersi di un profilo falso e di una foto fatta con l'IA. Ma quando hanno un dubbio su un contenuto, la metà non fa niente e l'azione più comune è guardare i commenti; chiedere a qualcuno è rarissimo. La passività riguarda tutti: chi ha poca fiducia è anzi ancora più passivo (14 su 21), quindi non si può dire che sia la sicurezza a rendere passivi. Due segnali di sovrastima: 14 dei 21 che non sanno cos'è un deepfake si danno 4-5 nel riconoscere foto IA, e più della metà di chi si sente capace di riconoscerle non saprebbe bene come agire se toccasse a loro. | D4: Q08–Q14, S15 | E4: Media: sono autovalutazioni, nell'intervista c'è un solo esercizio | F4: Un'autovalutazione alta non è una competenza misurata. Dai dati non si può dire che "non sanno riconoscere" i falsi: si può dire che la fiducia dichiarata non corrisponde ad azioni di verifica. | G4: Da verificare con un test pratico (es. riconoscere N foto vere/IA) per misurare la competenza reale. | H4: =COUNTIF(Fatti!$G:$G,A4) -> 1
A5: C4 | B5: Deepfake e contenuti falsi tra coetanei | C5: I contenuti modificati con l'IA girano tra coetanei (quasi 4 su 5 li hanno visti). Pochissimi li considerano una cosa seria: in genere "dipende" da quanto è pesante o sono uno scherzo. La gravità si giudica dalla reazione visibile della vittima ("se ride è uno scherzo"). Una studentessa racconta una chat creata contro di lei con le sue foto; la sua paura principale era che venissero modificate con l'IA. | D5: Q15, Q16, S16, S17, S19, S30, S33 | E5: Alta (questionario + intervista) | F5: Il questionario chiede cosa pensano "gli altri ragazzi", non il rispondente. Il caso di Aurora è una singola esperienza. | G5: Ipotesi: lavorare sulla percezione del danno ("ridere non vuol dire stare bene") e sul ruolo di chi assiste. | H5: =COUNTIF(Fatti!$G:$G,A5) -> 5
A6: C5 | B6: Riconoscere l'adescamento e le richieste di foto | C6: Davanti alla stessa chat di adescamento, le ragazze non concordano su quando scatta il campanello d'allarme: per alcune la confidenza eccessiva troppo presto, per altre la segretezza ("non dirlo ai tuoi") o la richiesta di una foto. Il rifiuto di mandare foto sessuali è netto, ma su una foto "normale" la soglia dipende dal tempo e dal sentirsi in confidenza. Le richieste di foto raccontate venivano da persone conosciute, non da sconosciuti. | D6: S20–S24, S08 | E6: Bassa-media: 5 ragazze di 13-14 anni, in gruppo | F6: Non generalizzabile al target, né ai ragazzi maschi. In gruppo le risposte si influenzano a vicenda. | G6: Ipotesi: un training che mostri l'escalation tipica (lusinga → segretezza → cambio di piattaforma → richiesta). Approfondire nelle prossime interviste i casi con persone "semi-conosciute". | H6: =COUNTIF(Fatti!$G:$G,A6) -> 5
A7: C6 | B7: Chiedere aiuto: a chi, e perché no | C7: Il primo confidente è un amico o un'amica; quasi 1 su 5 non ne parlerebbe con nessuno (nessuna delle 10 ragazze del questionario). Genitori e docenti sono scelti raramente come primo riferimento. Le ragazze esprimono riluttanza a coinvolgere i genitori (preferiscono "piuttosto i carabinieri") e temono che il prof veda la chat. Il docente attribuisce questa riluttanza a vergogna e paura di punizioni. Pochi sanno come agire se circolasse un'immagine falsa di sé. Per informarsi userebbero soprattutto Google, adulti, amici e IA; per confidarsi vogliono "una persona vera". | D7: Q17–Q20, S18, S25–S28, S31, D06–D08, D14–D17 | E7: Alta (tre fonti concordano) | F7: La risposta corale "prima con i genitori" (S27) è arrivata dopo una domanda diretta dell'intervistatore: va pesata meno. Le ragioni del docente (D15) sono sue opinioni. | G7: Ipotesi: gli amici sono il canale principale, quindi conviene preparare anche chi riceve la confidenza ("come aiutare un'amica"). Percorsi di aiuto chiari e graduali, che non obblighino a coinvolgere subito i genitori. | H7: =COUNTIF(Fatti!$G:$G,A7) -> 12
A8: C7 | B8: Prevenzione e ruolo della scuola | C8: Quasi nessuno ricorda attività di prevenzione; chi le cita parla di conferenze sul cyberbullismo o di educazione civica. A scuola la regolamentazione sull'IA è appena iniziata, mancano spazi di confronto tra studenti e il telefono è vietato. Nell'unico caso concreto raccontato, la scuola non è intervenuta in modo percepito come adeguato. Alcuni rispondenti chiedono più informazione. | D8: Q21, Q23, D01–D05, D07, D10, D12, D13, S32 | E8: Media | F8: Un solo docente e una sola scuola per le informazioni sull'istituto. "Non ricordo attività" non significa che non ce ne siano state. | G8: Con il divieto del telefono a scuola, lo strumento va pensato per l'uso fuori dall'orario scolastico (o con dispositivi della scuola). | H8: =COUNTIF(Fatti!$G:$G,A8) -> 10
A9: C8 | B9: Idea di progetto: forum anonimo e supporto | C9: Il forum riceve un interesse condizionato: sì se è anonimo (le ragazze citano NGL) e se si è sicuri che gli altri siano chi dicono. Un'intervistata dubita che molti racconterebbero la propria esperienza. Il docente lo ritiene utile per sentirsi meno soli, ma chiede supervisione discreta, protezione dagli screenshot e un accesso facile all'aiuto (esperti, numeri utili). Nel questionario solo il 4% cercherebbe informazioni in un forum. | D9: S29, S28, D09, D19–D23, Q20 | E9: Media-bassa | F9: L'idea del forum è stata proposta dagli intervistatori: c'è il rischio di risposte compiacenti. Il dato del questionario (4%) riguarda la ricerca di informazioni, non la condivisione. | G9: Tensione da risolvere: anonimato vs autenticità vs supervisione. Da verificare se i ragazzi leggerebbero esperienze altrui anche senza scriverne. | H9: =COUNTIF(Fatti!$G:$G,A9) -> 7
A10: C9 | B10: Come comunicare con i ragazzi | C10: Il docente consiglia un tono alla pari, un linguaggio semplice e diretto e nessuna imposizione: ciò che sembra imposto viene rifiutato. Racconta che una domanda amichevole è bastata a far aprire uno studente. | D10: D11, D18 | E10: Bassa: una sola fonte | F10: È l'esperienza di un singolo docente. | G10: Da verificare con i ragazzi (es. confronto tra testi con toni diversi). | H10: =COUNTIF(Fatti!$G:$G,A10) -> 2

Sheet Fatti
A1: Tabella dei fatti – una riga per ogni elemento rilevato (dati, non interpretazioni)
A2: S = intervista di gruppo alle studentesse (07/10) · D = intervista al docente (09/10) · Q = questionario online. Nomi delle studentesse di fantasia. La colonna Categoria rimanda al foglio "Pattern".
A4: ID | B4: Fonte | C4: Chi | D4: Tema / domanda | E4: Fatto osservato | F4: Riferimento audio | G4: Categoria | H4: Nome categoria | I4: NOTE
A5: S01 | B5: Intervista studentesse 07/10 | C5: Giulia, Sofia, Martina | D5: Abitudini online | E5: Scrivono soprattutto (Giulia) o solo (Sofia, Martina) con persone che conoscono. | G5: C1 | H5: =IFERROR(INDEX(Pattern!$B:$B,MATCH(G5,Pattern!$A:$A,0)),"") -> Abitudini online e contatti con sconosciuti
A6: S02 | B6: Intervista studentesse 07/10 | C6: Aurora | D6: Abitudini online | E6: Le è capitato di interagire anche con persone che non conosce. | G6: C1 | H6: =IFERROR(INDEX(Pattern!$B:$B,MATCH(G6,Pattern!$A:$A,0)),"") -> Abitudini online e contatti con sconosciuti
A7: S03 | B7: Intervista studentesse 07/10 | C7: Tutte (5) | D7: Profili social | E7: Tutte hanno il profilo privato. | G7: C1 | H7: =IFERROR(INDEX(Pattern!$B:$B,MATCH(G7,Pattern!$A:$A,0)),"") -> Abitudini online e contatti con sconosciuti
A8: S04 | B8: Intervista studentesse 07/10 | C8: Tutte (5) | D8: Profili social | E8: Giulia l'ha reso privato su consiglio della madre; Aurora, Martina e Chiara da sole "per precauzione"; Sofia "perché non voglio che altre persone lo vedano". | G8: C1 | H8: =IFERROR(INDEX(Pattern!$B:$B,MATCH(G8,Pattern!$A:$A,0)),"") -> Abitudini online e contatti con sconosciuti
A9: S05 | B9: Intervista studentesse 07/10 | C9: Giulia | D9: Contatti con sconosciuti | E9: Ha un'amica conosciuta online, ma non ha avuto diffidenza "perché già la conoscevo tramite un po' di amiche". Nessun contatto con persone del tutto sconosciute. | G9: C2 | H9: =IFERROR(INDEX(Pattern!$B:$B,MATCH(G9,Pattern!$A:$A,0)),"") -> Come valutano se un profilo è affidabile
A10: S06 | B10: Intervista studentesse 07/10 | C10: Sofia, Martina | D10: Contatti con sconosciuti | E10: Una volta contattate da uno sconosciuto: bloccato subito ("non mi fidavo" / "non lo conosceva nessuno"). | G10: C1 | H10: =IFERROR(INDEX(Pattern!$B:$B,MATCH(G10,Pattern!$A:$A,0)),"") -> Abitudini online e contatti con sconosciuti
A11: S07 | B11: Intervista studentesse 07/10 | C11: Chiara | D11: Contatti con sconosciuti | E11: "Io mai nessuno online." | G11: C1 | H11: =IFERROR(INDEX(Pattern!$B:$B,MATCH(G11,Pattern!$A:$A,0)),"") -> Abitudini online e contatti con sconosciuti
A12: S08 | B12: Intervista studentesse 07/10 | C12: Aurora | D12: Contatti con sconosciuti | E12: Ha accettato un ragazzo sconosciuto perché le amiche lo seguivano; "sembrava più grande"; dovevano uscire, poi ha perso interesse perché non sapeva bene "com'era fatto". | F12: Estratto 1 (02:50) | G12: C2 | H12: =IFERROR(INDEX(Pattern!$B:$B,MATCH(G12,Pattern!$A:$A,0)),"") -> Come valutano se un profilo è affidabile
A13: S09 | B13: Intervista studentesse 07/10 | C13: Giulia | D13: Segnali di affidabilità | E13: Primo segnale di dubbio: se è "aggressivo, violento". Con amici in comune "mi fa pensare che è a posto"; senza, diventa più diffidente. | G13: C2 | H13: =IFERROR(INDEX(Pattern!$B:$B,MATCH(G13,Pattern!$A:$A,0)),"") -> Come valutano se un profilo è affidabile
A14: S10 | B14: Intervista studentesse 07/10 | C14: Sofia | D14: Segnali di affidabilità | E14: Si insospettisce "se inizia a fare domande un po' scomode". | G14: C2 | H14: =IFERROR(INDEX(Pattern!$B:$B,MATCH(G14,Pattern!$A:$A,0)),"") -> Come valutano se un profilo è affidabile
A15: S11 | B15: Intervista studentesse 07/10 | C15: Aurora | D15: Segnali di affidabilità | E15: Guarda la foto profilo; evita chi pubblica storie con pistole (pur conoscendo "brave persone" che lo fanno); evita chi chiede dove abita. | G15: C2 | H15: =IFERROR(INDEX(Pattern!$B:$B,MATCH(G15,Pattern!$A:$A,0)),"") -> Come valutano se un profilo è affidabile
A16: S12 | B16: Intervista studentesse 07/10 | C16: Chiara | D16: Segnali di affidabilità | E16: Su WhatsApp guarda la provenienza del numero e blocca i numeri esteri; su Instagram prima segue lei lo sconosciuto e poi, se va bene, lo accetta. | G16: C2 | H16: =IFERROR(INDEX(Pattern!$B:$B,MATCH(G16,Pattern!$A:$A,0)),"") -> Come valutano se un profilo è affidabile
A17: S13 | B17: Intervista studentesse 07/10 | C17: Sofia, Aurora, Giulia | D17: Esercizio 1 – due profili | E17: Giudicano i profili da aspetto e "normalità" delle foto ("sembra fake tantissimo", "questo è più bello", "sembra più una persona vera"); notano il tag dell'università. Sofia: "l'apparenza può ingannare". | G17: C2 | H17: =IFERROR(INDEX(Pattern!$B:$B,MATCH(G17,Pattern!$A:$A,0)),"") -> Come valutano se un profilo è affidabile
A18: S14 | B18: Intervista studentesse 07/10 | C18: Aurora, Giulia, Chiara | D18: Esercizio 1 – due profili | E18: Usano i follower come indizio ma in modo incoerente: 436 follower "non so"; per Aurora 600 follower "già mi sembra una cosa finta". Confrontano con il proprio numero di follower. | G18: C2 | H18: =IFERROR(INDEX(Pattern!$B:$B,MATCH(G18,Pattern!$A:$A,0)),"") -> Come valutano se un profilo è affidabile | I18: questo può essere un esempio di indicatore errato/incoerente da usare.
A19: S15 | B19: Intervista studentesse 07/10 | C19: Giulia, Aurora | D19: Esercizio 2 – foto IA | E19: Il gruppo individua correttamente la foto generata con l'IA (dopo averla ingrandita). Aurora motiva il giudizio sull'altro profilo con la "faccia" della persona. | G19: C3 | H19: =IFERROR(INDEX(Pattern!$B:$B,MATCH(G19,Pattern!$A:$A,0)),"") -> Fiducia nelle proprie capacità vs comportamenti reali
A20: S16 | B20: Intervista studentesse 07/10 | C20: Sofia, Giulia | D20: Deepfake a scuola | E20: Criterio per distinguere scherzo e cosa seria: "quando c'è uno scherzo si ride e basta", "se si fanno battute", se la vittima ride. Alla domanda sul disagio nascosto: "si capisce, dai". | F20: Estratto 2 (08:44) | G20: C4 | H20: =IFERROR(INDEX(Pattern!$B:$B,MATCH(G20,Pattern!$A:$A,0)),"") -> Deepfake e contenuti falsi tra coetanei | I20: altro possibile fallacia argomentativa. bias da eccesso di fiducia?(overconfidence bias)
A21: S17 | B21: Intervista studentesse 07/10 | C21: Aurora | D21: Deepfake a scuola | E21: Nei casi seri: parlarne "in modo discreto, senza prendere le parti e non esprirere opinioni senza conoscere a fondo la situazione. Cita un'esperienza vissuta quest'anno. | F21: Estratto 2 | G21: C4 | H21: =IFERROR(INDEX(Pattern!$B:$B,MATCH(G21,Pattern!$A:$A,0)),"") -> Deepfake e contenuti falsi tra coetanei
A22: S18 | B22: Intervista studentesse 07/10 | C22: Sofia, Chiara, Martina, Aurora | D22: Deepfake a scuola | E22: Se la vittima è in difficoltà: "vado da lei e ci parlo io", "offriamo la nostra disponibilità", "parlerei con il prof al posto suo", "ci parlo io con chi di dovere". | F22: Estratto 2 | G22: C6 | H22: =IFERROR(INDEX(Pattern!$B:$B,MATCH(G22,Pattern!$A:$A,0)),"") -> Chiedere aiuto: a chi, e perché no | I22: mette in luce la utilità del nostro spazio forum
A23: S19 | B23: Intervista studentesse 07/10 | C23: Sofia, Aurora | D23: Deepfake a scuola | E23: Coinvolgere un adulto "dipende da quanto è grave": una presa in giro è diverso da cyberbullismo. | F23: Estratto 2 | G23: C4 | H23: =IFERROR(INDEX(Pattern!$B:$B,MATCH(G23,Pattern!$A:$A,0)),"") -> Deepfake e contenuti falsi tra coetanei | I23: anche qua si evidenzia il rischio di sottostimare il problema
A24: S20 | B24: Intervista studentesse 07/10 | C24: Tutte | D24: Esercizio 3 – chat di adescamento | E24: Non concordano sul primo messaggio sospetto: Sofia indica "sei molto più matura" / "nessuno mi capisce come te" (troppo presto); Aurora "mandami una foto" e poi "non dirlo ai tuoi"; Martina "non dirlo ai tuoi"; Aurora cambia idea più volte ("dal 5... dal 6... almeno dal 4"). | G24: C5 | H24: =IFERROR(INDEX(Pattern!$B:$B,MATCH(G24,Pattern!$A:$A,0)),"") -> Riconoscere l'adescamento e le richieste di foto | I24: si evidenzia l'importanza di includere nel training sul definire i boundaries e il rispetto per gli altri e per se stessi.
A25: S21 | B25: Intervista studentesse 07/10 | C25: Aurora, Sofia | D25: Esercizio 3 – chat di adescamento | E25: Aurora: "a me va bene se mi scrive strano", legge le lusinghe come "carenza affettiva" dell'altro. Sofia: "dopo due giorni è esagerato". | F25: Estratto 3 (13:13) | G25: C5 | H25: =IFERROR(INDEX(Pattern!$B:$B,MATCH(G25,Pattern!$A:$A,0)),"") -> Riconoscere l'adescamento e le richieste di foto
A26: S22 | B26: Intervista studentesse 07/10 | C26: Aurora, Giulia | D26: Richiesta di foto | E26: A entrambe è stata chiesta una foto da qualcuno che conoscevano (per Giulia un ragazzo della stessa scuola). Aurora non l'ha mandata e l'ha bloccato. | F26: Estratto 4 (14:02) | G26: C5 | H26: =IFERROR(INDEX(Pattern!$B:$B,MATCH(G26,Pattern!$A:$A,0)),"") -> Riconoscere l'adescamento e le richieste di foto
A27: S23 | B27: Intervista studentesse 07/10 | C27: Aurora, Sofia | D27: Richiesta di foto | E27: Dopo un mese di conoscenza Aurora "magari gliela mando", "dipende che foto", anche senza essersi mai visti "se so chi è". Sofia: "solo online no", bisogna vedersi prima. Disaccordo aperto. | F27: Estratto 4 | G27: C5 | H27: =IFERROR(INDEX(Pattern!$B:$B,MATCH(G27,Pattern!$A:$A,0)),"") -> Riconoscere l'adescamento e le richieste di foto | I27: aurora potenziale utente estremo base molto inesperto
A28: S24 | B28: Intervista studentesse 07/10 | C28: Tutte | D28: Richiesta di foto | E28: Una foto a sfondo sessuale non la manderebbero a nessuno, nemmeno a persone conosciute. | F28: Estratto 4 | G28: C5 | H28: =IFERROR(INDEX(Pattern!$B:$B,MATCH(G28,Pattern!$A:$A,0)),"") -> Riconoscere l'adescamento e le richieste di foto
A29: S25 | B29: Intervista studentesse 07/10 | C29: Giulia, Martina, Sofia, Chiara | D29: Minacce | E29: Amico minacciato di diffusione di una foto: Giulia e Martina "bloccarlo e segnalarlo"; Sofia "andrei dai carabinieri"; Chiara "dal prof"; Giulia obietta "ma poi il prof vede la chat". | F29: Estratto 5 (16:43) | G29: C6 | H29: =IFERROR(INDEX(Pattern!$B:$B,MATCH(G29,Pattern!$A:$A,0)),"") -> Chiedere aiuto: a chi, e perché no
A30: S26 | B30: Intervista studentesse 07/10 | C30: Aurora | D30: Minacce | E30: "Io non voglio dirlo a mia mamma, quindi piuttosto vado dai carabinieri." | F30: Estratto 5 | G30: C6 | H30: =IFERROR(INDEX(Pattern!$B:$B,MATCH(G30,Pattern!$A:$A,0)),"") -> Chiedere aiuto: a chi, e perché no
A31: S27 | B31: Intervista studentesse 07/10 | C31: Tutte | D31: Minacce | E31: Alla domanda diretta "non ne parlereste prima con i genitori?" rispondono in coro: "prima con i genitori e poi andiamo insieme dai carabinieri". | F31: Estratto 5 | G31: C6 | H31: =IFERROR(INDEX(Pattern!$B:$B,MATCH(G31,Pattern!$A:$A,0)),"") -> Chiedere aiuto: a chi, e perché no
A32: S28 | B32: Intervista studentesse 07/10 | C32: Tutte, Aurora | D32: Minacce | E32: Se dovessero decidere da sole: "a un'amica". Aurora accenna all'IA, ma le altre su IA o forum: "no, no", "vado subito da una persona vera, per confidarmi". | F32: Estratto 5 | G32: C6 | H32: =IFERROR(INDEX(Pattern!$B:$B,MATCH(G32,Pattern!$A:$A,0)),"") -> Chiedere aiuto: a chi, e perché no | I32: ebidenziato un problema: bisogno di parlare con una persona vera --> il forum serve a questo
A33: S29 | B33: Intervista studentesse 07/10 | C33: Sofia, Giulia, tutte | D33: Forum anonimo | E33: Sofia: utile "se sei sicura che sono le persone che dicono di essere"; Giulia: "non so quanta gente riuscirebbe a dire quello che è successo". Saputo che è anonimo: tutte "ah, sì"; Giulia: "come NGL". | F33: Estratto 6 (18:37) | G33: C8 | H33: =IFERROR(INDEX(Pattern!$B:$B,MATCH(G33,Pattern!$A:$A,0)),"") -> Idea di progetto: forum anonimo e supporto | I33: giulia evidenzia il blocco a parlare di cose difficili. l'anonimità sembra dover essere un requisito del forum.
A34: S30 | B34: Intervista studentesse 07/10 | C34: Aurora | D34: Esperienza personale | E34: Alcune compagne hanno creato una chat di gruppo contro di lei con insulti e sue foto (prese da Instagram o mandate alle amiche). L'ha scoperto tramite un amico. | G34: C4 | H34: =IFERROR(INDEX(Pattern!$B:$B,MATCH(G34,Pattern!$A:$A,0)),"") -> Deepfake e contenuti falsi tra coetanei | I34: aurora si conferma utente estremo
A35: S31 | B35: Intervista studentesse 07/10 | C35: Aurora | D35: Esperienza personale | E35: Non voleva dirlo ai genitori; l'ha detto solo alle amiche, che l'hanno convinta: l'hanno detto insieme ai genitori. | G35: C6 | H35: =IFERROR(INDEX(Pattern!$B:$B,MATCH(G35,Pattern!$A:$A,0)),"") -> Chiedere aiuto: a chi, e perché no | I35: sottolinea il bisogno di una cerchia di supporto
A36: S32 | B36: Intervista studentesse 07/10 | C36: Aurora, Giulia, Martina | D36: Esperienza personale | E36: I prof si sono allarmati; i genitori sono andati in presidenza ma "il preside non ha voluto fare nulla". Giulia: "alla fine non hanno fatto abbastanza". | G36: C7 | H36: =IFERROR(INDEX(Pattern!$B:$B,MATCH(G36,Pattern!$A:$A,0)),"") -> Prevenzione e ruolo della scuola | I36: non sempre le istituzionisono in grado di rispondere: a volte si minimizza il problema o le sue conseguenze sulla vittima
A37: S33 | B37: Intervista studentesse 07/10 | C37: Aurora | D37: Esperienza personale | E37: La sua paura principale era che le foto venissero modificate con l'IA ("si può fare qualunque cosa, anche se non è vera"). Non è successo. | G37: C4 | H37: =IFERROR(INDEX(Pattern!$B:$B,MATCH(G37,Pattern!$A:$A,0)),"") -> Deepfake e contenuti falsi tra coetanei
A40: D01 | B40: Intervista docente 09/10 | C40: Docente | D40: Scuola e IA | E40: La nuova dirigente ha emanato un atto di indirizzo per regolamentare l'uso dell'IA nel PTOF; non è ancora stato attivato nulla; i docenti non sono obbligati a usarla. | G40: C7 | H40: =IFERROR(INDEX(Pattern!$B:$B,MATCH(G40,Pattern!$A:$A,0)),"") -> Prevenzione e ruolo della scuola | I40: si sottoliea la lentezza di ripsposta da parte delle istituzioni
A41: D02 | B41: Intervista docente 09/10 | C41: Docente | D41: Scuola e IA | E41: Non ha notato cambiamenti nei propri insegnamenti(matematica e fisica) né nelle relazioni tra studenti; non ha mai sentito studenti parlare di IA. | G41: C7 | H41: =IFERROR(INDEX(Pattern!$B:$B,MATCH(G41,Pattern!$A:$A,0)),"") -> Prevenzione e ruolo della scuola
A42: D03 | B42: Intervista docente 09/10 | C42: Docente | D42: Scuola e IA | E42: L'anno scorso in una classe si è tenuto un corso sull'IA; alcuni studenti si sono mostrati "parecchio ferrati". | G42: C7 | H42: =IFERROR(INDEX(Pattern!$B:$B,MATCH(G42,Pattern!$A:$A,0)),"") -> Prevenzione e ruolo della scuola
A43: D04 | B43: Intervista docente 09/10 | C43: Docente | D43: Scuola e IA | E43: Ritiene utile uno strumento educativo IA, "non solo per i ragazzi: anche per gli adulti, per tutti". | G43: C7 | H43: =IFERROR(INDEX(Pattern!$B:$B,MATCH(G43,Pattern!$A:$A,0)),"") -> Prevenzione e ruolo della scuola | I43: anche gli adulti potrebbero non essere in gr<o d idare supporto ai propri figli.
...

Sheet Incroci
A1: Incroci tra domande (base: rispondenti con consenso)
A3: Fiducia nel riconoscere foto IA × cosa hanno fatto l'ultima volta che hanno dubitato
B4: Ha fatto qualcosa | C4: Non ha fatto niente | D4: Totale
A5: Fiducia 1-3 | B5: 7 | C5: 14 | D5: =SUM(B5:C5) -> 21
A6: Fiducia alta (4-5) | B6: 42 | C6: 35 | D6: =SUM(B6:C6) -> 77
A8: Fiducia nel riconoscere foto IA × saprebbe come agire
B9: Saper agire 1-3 | C9: Saprebbe agire (4-5) | D9: Totale
A10: Fiducia 1-3 | B10: 18 | C10: 3 | D10: =SUM(B10:C10) -> 21
A11: Fiducia alta (4-5) | B11: 41 | C11: 35 | D11: =SUM(B11:C11) -> 76
A13: Sa cos'è un deepfake × fiducia nel riconoscere foto IA
B14: Fiducia 1-3 | C14: Fiducia alta (4-5) | D14: Totale
A15: ne ho sentito parlare | B15: 5 | C15: 13 | D15: =SUM(B15:C15) -> 18
A16: no | B16: 7 | C16: 14 | D16: =SUM(B16:C16) -> 21
A17: sì, saprei spiegarlo | B17: 9 | C17: 50 | D17: =SUM(B17:C17) -> 59
A19: Genere × primo confidente
A20: Attenzione: solo 10 femmine e 4 non binari, confronto indicativo.
B21: altro | C21: amico o amica | D21: fratello o sorella | E21: genitore | F21: nessuno | G21: Totale
A22: Femmina | B22: 0 | C22: 9 | D22: 0 | E22: 1 | F22: 0 | G22: =SUM(B22:F22) -> 10
A23: Maschio | B23: 10 | C23: 41 | D23: 6 | E23: 9 | F23: 15 | G23: =SUM(B23:F23) -> 81
A24: Non binario | B24: 1 | C24: 1 | D24: 1 | E24: 0 | F24: 1 | G24: =SUM(B24:F24) -> 4
A25: Preferisco non rispondere | B25: 0 | C25: 0 | D25: 0 | E25: 0 | F25: 1 | G25: =SUM(B25:F25) -> 1
A27: Età × come viene considerato un deepfake tra coetanei
B28: Come un semplice scherzo per farsi una risata | C28: Come una cosa seria e potenzialmente dannosa | D28: Dipende da quanto è pesante o imbarazzante il contenuto | E28: Non ci facciamo troppo caso o non saprei | F28: Totale
A29: 14 | B29: 1 | C29: 0 | D29: 7 | E29: 3 | F29: =SUM(B29:E29) -> 11
A30: 15 | B30: 5 | C30: 1 | D30: 19 | E30: 2 | F30: =SUM(B30:E30) -> 27
A31: 16 | B31: 15 | C31: 1 | D31: 12 | E31: 4 | F31: =SUM(B31:E31) -> 32
A32: 17 | B32: 14 | C32: 2 | D32: 10 | E32: 2 | F32: =SUM(B32:E32) -> 28
