Workbook

Sheet Leggimi
A1: Needfinding in classe - analisi delle risposte
A2: Progetto HCI "Chi c'è dall'altra parte?" - attività in una classe di liceo (focus group a squadre)
A4: Fonti analizzate
A5: Fonte | B5: Contenuto
A6: Schede di lavoro (5 squadre) | B6: Tontony (5), Divo (5), Biscotto (4), Team Pasqua (5), Dream Team (4): 23 studenti in totale. Fasi 0, 1, 1bis, 2 e risposte alla tavola rotonda (TR1-TR4).
A7: Appunti di osservazione del team | B7: Note prese seguendo i gruppi durante la Fase 2 (chat). Codici OSS-01 ... OSS-28.
A8: Presentazione in classe | B8: Struttura dell'attività: Sfida reale vs IA, Tavola rotonda, Co-design. Da qui le soluzioni delle coppie della Fase 1bis.
A9: Soluzioni del quiz foto | B9: Fornite dal team: L0 V,F,F - L1 F,V,V - L2 V,V,F - L3 F,V,F - L4 tutte generate con l'IA.
A11: Codici usati in tutti i documenti (tracciabilità)
A12: Codice | B12: Significato
A13: TON, DIV, BIS, PAS, DRE | B13: Squadre: Tontony, Divo, Biscotto, Team Pasqua, Dream Team
A14: F0 | B14: Fase 0 - autovalutazione individuale (voto 1-10)
A15: F1-Lx-Fy | B15: Fase 1 - quiz foto, livello x, foto y (es. F1-L4-F3)
A16: F1bis-A/B/C | B16: Fase 1bis - coppie di foto (quale è stata generata dall'altra)
A17: CH-[squadra]-Cx | B17: Note scritte dalla squadra sulla chat x (es. CH-DRE-C4)
A18: OSS-nn | B18: Appunti di osservazione del team
A19: TR1...TR4-[squadra] | B19: Risposta della squadra alla domanda n della tavola rotonda (es. TR4-BIS)
A20: B1...B8 | B20: Bisogni consolidati (vedi foglio 'Analisi tematica' e documento dei bisogni)
A22: Convenzioni e limiti della trascrizione
A23: • | B23: Le schede sono scritte a mano: dove la lettura è incerta il testo è segnato con [lettura incerta].
A24: • | B24: Risposte con caselle segnate in modo contraddittorio sono marcate '?' ed escluse dai punteggi (colonna 'Esito' = n.v.).
A25: • | B25: Tontony ha compilato i livelli 3-4 sia in tabella sia su un foglio aggiunto: dove i due non coincidono vale il dato marcato '?'.
A26: • | B26: Biscotto non ha cerchiato la difficoltà; alcune squadre non hanno compilato la Fase 1bis-C e la Chat 6.
A27: • | B27: Le domande della Chat 2 e della Chat 6 non sono state discusse negli appunti: i dati su quelle chat sono solo quelli delle schede.
A28: • | B28: I numeri sono piccoli (5 squadre, 23 studenti): le percentuali servono a leggere tendenze, non hanno valore statistico.
A30: Fogli del file
A31: Foglio | B31: Contenuto
A32: Sintesi | B32: Analisi complessiva: numeri chiave, grafici, punti comuni, divergenze, sorprese
A33: F0 Autovalutazione | B33: Voti individuali e medie per squadra
A34: F1 Foto (dati) | B34: Ogni risposta del quiz foto con esito calcolato, difficoltà e indizio dichiarato
A35: F1 Foto (matrice) | B35: Risposte per foto e squadra, con quante squadre hanno indovinato
A36: F1bis Coppie | B36: Coppie di foto: quale è generata e com'è la foto rimasta
A37: Indizi usati | B37: Su cosa si basano i ragazzi per dire 'è IA' e quanto quell'indizio li porta alla risposta giusta
A38: F2 Chat | B38: Giudizio sulle chat, note dei gruppi e osservazioni del team
A39: Tavola rotonda | B39: Risposte TR1-TR4 per squadra con punti comuni e divergenze
A40: Appunti osservazione | B40: Appunti del team codificati per tema
A41: Analisi tematica | B41: Temi emersi, evidenze, convergenze/divergenze e bisogno collegato

Sheet Sintesi
A1: Sintesi complessiva
A2: I numeri sono calcolati dagli altri fogli; i testi sono l'analisi del team
A4: Numeri chiave
A5: Indicatore | B5: Valore
A6: Studenti coinvolti | B6: ='F0 Autovalutazione'!B35 -> 23
A7: Autovalutazione media - riconoscere un falso (1-10) | B7: ='F0 Autovalutazione'!C35 -> 6.6086957
A8: Autovalutazione media - riconoscere adescamento (1-10) | B8: ='F0 Autovalutazione'!D35 -> 7
A9: Accuratezza quiz foto, tutti i livelli | B9: ='F1 Foto (dati)'!E93 -> 0.79487179
A10: Accuratezza livelli 0-1 | B10: =('F1 Foto (dati)'!D97+'F1 Foto (dati)'!D98)/('F1 Foto (dati)'!C97+'F1 Foto (dati)'!C98) -> 0.93333333
A11: Accuratezza livello 4 | B11: ='F1 Foto (dati)'!E101 -> 0.52631579
A12: Foto IA non riconosciute (falsi negativi) | B12: ='F1 Foto (dati)'!G93 -> 11
A13: Foto reali giudicate IA (falsi positivi) | B13: ='F1 Foto (dati)'!F93 -> 5
A14: Chat giudicate sospette all'unanimità (su 5) | B14: =COUNTIF('F2 Chat'!G5:G9,5) -> 0
A16: Autovalutazione e risultato reale per squadra
A17: Squadra | B17: Autovalutazione foto (media /10) | C17: Autovalutazione in % | D17: Accuratezza quiz (tutti i livelli) | E17: Accuratezza livello 4 | F17: Scarto L4 - autovalutazione
A18: Tontony | B18: ='F0 Autovalutazione'!C30 -> 6.8 | C18: =B18/10 -> 0.68 | D18: ='F1 Foto (dati)'!E88 -> 0.86666667 | E18: =COUNTIFS('F1 Foto (dati)'!$B$5:$B$84,A18,'F1 Foto (dati)'!$C$5:$C$84,"L4",'F1 Foto (dati)'!$G$5:$G$84,1)/COUNTIFS('F1 Foto (dati)'!$B$5:$B$84,A18,'F1 Foto (dati)'!$C$5:$C$84,"L4",'F1 Foto (dati)'!$G$5:$G$84,"<>n.v.") -> 0.66666667 | F18: =E18-C18 -> -0.013333333
A19: Divo | B19: ='F0 Autovalutazione'!C31 -> 7 | C19: =B19/10 -> 0.7 | D19: ='F1 Foto (dati)'!E89 -> 0.8125 | E19: =COUNTIFS('F1 Foto (dati)'!$B$5:$B$84,A19,'F1 Foto (dati)'!$C$5:$C$84,"L4",'F1 Foto (dati)'!$G$5:$G$84,1)/COUNTIFS('F1 Foto (dati)'!$B$5:$B$84,A19,'F1 Foto (dati)'!$C$5:$C$84,"L4",'F1 Foto (dati)'!$G$5:$G$84,"<>n.v.") -> 0.5 | F19: =E19-C19 -> -0.2
A20: Biscotto | B20: ='F0 Autovalutazione'!C32 -> 6.5 | C20: =B20/10 -> 0.65 | D20: ='F1 Foto (dati)'!E90 -> 0.6875 | E20: =COUNTIFS('F1 Foto (dati)'!$B$5:$B$84,A20,'F1 Foto (dati)'!$C$5:$C$84,"L4",'F1 Foto (dati)'!$G$5:$G$84,1)/COUNTIFS('F1 Foto (dati)'!$B$5:$B$84,A20,'F1 Foto (dati)'!$C$5:$C$84,"L4",'F1 Foto (dati)'!$G$5:$G$84,"<>n.v.") -> 0.25 | F20: =E20-C20 -> -0.4
A21: Team Pasqua | B21: ='F0 Autovalutazione'!C33 -> 6 | C21: =B21/10 -> 0.6 | D21: ='F1 Foto (dati)'!E91 -> 0.8125 | E21: =COUNTIFS('F1 Foto (dati)'!$B$5:$B$84,A21,'F1 Foto (dati)'!$C$5:$C$84,"L4",'F1 Foto (dati)'!$G$5:$G$84,1)/COUNTIFS('F1 Foto (dati)'!$B$5:$B$84,A21,'F1 Foto (dati)'!$C$5:$C$84,"L4",'F1 Foto (dati)'!$G$5:$G$84,"<>n.v.") -> 0.75 | F21: =E21-C21 -> 0.15
A22: Dream Team | B22: ='F0 Autovalutazione'!C34 -> 6.75 | C22: =B22/10 -> 0.675 | D22: ='F1 Foto (dati)'!E92 -> 0.8 | E22: =COUNTIFS('F1 Foto (dati)'!$B$5:$B$84,A22,'F1 Foto (dati)'!$C$5:$C$84,"L4",'F1 Foto (dati)'!$G$5:$G$84,1)/COUNTIFS('F1 Foto (dati)'!$B$5:$B$84,A22,'F1 Foto (dati)'!$C$5:$C$84,"L4",'F1 Foto (dati)'!$G$5:$G$84,"<>n.v.") -> 0.5 | F22: =E22-C22 -> -0.175
A23: Lettura | B23: Sul totale le squadre fanno meglio di quanto dichiarano, perché molte foto erano facili. Ma la fiducia dichiarata (6-7/10) non cambia con la difficoltà: al livello 4, cioè con contenuti realistici come quelli che un adescatore userebbe, quattro squadre su cinque scendono sotto la propria autovalutazione. La squadra più prudente (Team Pasqua) è l'unica che al livello 4 supera il proprio voto; Biscotto, tra le più sicure sulle chat, è quella che sbaglia di più.
A25: Accuratezza per livello
A26: Livello | B26: Accuratezza
A27: Livello 0 | B27: ='F1 Foto (dati)'!E97 -> 1 | C27: estremamente facile
A28: Livello 1 | B28: ='F1 Foto (dati)'!E98 -> 0.86666667 | C28: facile
A29: Livello 2 | B29: ='F1 Foto (dati)'!E99 -> 0.8 | C29: medio
A30: Livello 3 | B30: ='F1 Foto (dati)'!E100 -> 0.85714286 | C30: difficile
A31: Livello 4 | B31: ='F1 Foto (dati)'!E101 -> 0.52631579 | C31: molto difficile
A33: Analisi complessiva
A34: Punti comuni | B34: • Tutte le squadre riconoscono senza fatica le foto facili e le richieste esplicite in chat (foto, dati personali, cambio di app, 'vieni da sola'). • Si sentono 'abbastanza' capaci (voti tra 6 e 8) e basano il giudizio su dettagli visivi ('troppo perfetto', sfondo) e su segnali sociali (amici in comune, storie, averlo visto a scuola). • Nessuno manderebbe la foto richiesta in Chat 5; la reazione più citata è bloccare o smettere di rispondere. • Tutte le squadre descrivono una difficoltà a parlarne con gli adulti (paura del giudizio, delle conseguenze, di perdere libertà). • L'attività è piaciuta perché attiva: chiedono strumenti interattivi e non 'la solita lezione'.
A35: Divergenze | B35: • Chat 1, 2 e 3 dividono le squadre: le stesse conversazioni sono 'normali' per alcuni e sospette per altri, segno che i segnali iniziali non sono condivisi. • Deepfake nel gruppo (Chat 5.1): da 'non si fa mai' a 'è solo uno scherzo', anche quando la vittima chiede di togliere la foto. • A chi chiedere aiuto: genitori (PAS, OSS-22), prima sorella/amica e poi genitori (OSS-20), polizia postale saltando i genitori (OSS-18). • Forum: leggere sì, scrivere poco; i commenti piacciono solo se moderati, una squadra non condividerebbe nulla di personale. • Tutor: utilissimo per Divo, inutile per Team Pasqua (meglio qualcuno che ti conosce), ponte verso i genitori per Dream Team.
A36: Sorprese (momenti da approfondire) | B36: • Una foto del livello 4 non è stata riconosciuta da nessuna squadra e la coppia A (doppia manipolazione) ha ingannato due squadre: al livello 4 quattro squadre su cinque restano sotto la propria autovalutazione. • Una foto viene creduta reale 'perché la faccia sembra conosciuta': la familiarità abbassa le difese. • 'Se lo conosco da un po' ci può stare' e nessuno chiede prove dell'identità: la fiducia costruita nel tempo è il punto debole, ed è proprio la strategia dell'adescatore. • Le foto reali con filtri vengono scambiate per IA: il sospetto generico non coincide con la capacità di riconoscere.
A37: Implicazioni per i bisogni | B37: • I cinque bisogni già individuati sono confermati dai dati (B1-B5), con alcune precisazioni: B1 descrive soprattutto il 'come' (modalità), B2 deve garantire anonimato e moderazione, B3 deve includere i segnali graduali. • Emergono tre bisogni nuovi: B6 verificare chi c'è dall'altra parte, B7 poter coinvolgere un adulto senza paura, B8 capire quando un contenuto manipolato smette di essere uno scherzo. • Candidati per i 3-4 bisogni da selezionare: B4, B6, B7, B8 (evidenze più forti e meno coperti da strumenti esistenti), con B1 e B2 come requisiti trasversali su come il servizio coinvolge i ragazzi.

Sheet F0 Autovalutazione
A1: Fase 0 - Quanto vi sentite capaci? (voto individuale 1-10)
A4: Squadra | B4: Componente | C4: Riconoscere foto/contenuto falso | D4: Riconoscere adescamento in chat | E4: Nota
A5: Tontony | B5: A | C5: 7 | D5: 8
A6: Tontony | B6: B | C6: 6 | D6: 8
A7: Tontony | B7: C | C7: 6 | D7: 7
A8: Tontony | B8: D | C8: 7 | D8: 9
A9: Tontony | B9: E | C9: 8 | D9: 8
A10: Divo | B10: A | C10: 7 | D10: 8
A11: Divo | B11: B | C11: 7 | D11: 8
A12: Divo | B12: C | C12: 7 | D12: 7
A13: Divo | B13: D | C13: 8 | D13: 7
A14: Divo | B14: E | C14: 6 | D14: 7
A15: Biscotto | B15: A | C15: 7 | D15: 7
A16: Biscotto | B16: B | C16: 7 | D16: 8
... A25: Dream Team | B25: B | C25: 7 | D25: 5
A26: Dream Team | B26: C | C26: 7 | E26: Componente C: cerchiati sia 3 sia 8 nella colonna chat (valore escluso dalla media)
A27: Dream Team | B27: D | C27: 4 | D27: 6
A29: Squadra | B29: N. studenti | C29: Media foto | D29: Media chat | E29: Differenza chat - foto
A30: Tontony | B30: =COUNTIF($A$5:$A$27,A30) -> 5 | C30: =AVERAGEIF($A$5:$A$27,A30,$C$5:$C$27) -> 6.8 | D30: =AVERAGEIF($A$5:$A$27,A30,$D$5:$D$27) -> 8 | E30: =D30-C30 -> 1.2
A31: Divo | B31: =COUNTIF($A$5:$A$27,A31) -> 5 | C31: =AVERAGEIF($A$5:$A$27,A31,$C$5:$C$27) -> 7 | D31: =AVERAGEIF($A$5:$A$27,A31,$D$5:$D$27) -> 7.4 | E31: =D31-C31 -> 0.4
A32: Biscotto | B32: =COUNTIF($A$5:$A$27,A32) -> 4 | C32: =AVERAGEIF($A$5:$A$27,A32,$C$5:$C$27) -> 6.5 | D32: =AVERAGEIF($A$5:$A$27,A32,$D$5:$D$27) -> 8 | E32: =D32-C32 -> 1.5
A33: Team Pasqua | B33: =COUNTIF($A$5:$A$27,A33) -> 5 | C33: =AVERAGEIF($A$5:$A$27,A33,$C$5:$C$27) -> 6 | D33: =AVERAGEIF($A$5:$A$27,A33,$D$5:$D$27) -> 5.4 | E33: =D33-C33 -> -0.6
A34: Dream Team | B34: =COUNTIF($A$5:$A$27,A34) -> 4 | C34: =AVERAGEIF($A$5:$A$27,A34,$C$5:$C$27) -> 6.75 | D34: =AVERAGEIF($A$5:$A$27,A34,$D$5:$D$27) -> 6 | E34: =D34-C34 -> -0.75
A35: Totale classe | B35: =COUNTA($A$5:$A$27) -> 23 | C35: =AVERAGE($C$5:$C$27) -> 6.6086957 | D35: =AVERAGE($D$5:$D$27) -> 7 | E35: =D35-C35 -> 0.39130435
A37: Lettura | B37: Quasi tutti si collocano tra 6 e 8 su entrambe le abilità: nessuno si sente incapace, pochi si sentono sicurissimi. Ci si sente più capaci a riconoscere l'adescamento che a riconoscere un falso, tranne in Team Pasqua, che è la squadra più prudente su entrambe. I voti in blu sono dati trascritti dalle schede.

Sheet F1 Foto (dati)
A1: Fase 1 - Reale vs IA: tutte le risposte
A2: Esito = 1 se la risposta coincide con la soluzione, 0 se no, n.v. se la risposta è ambigua
A4: Chiave | B4: Squadra | C4: Livello | D4: Foto | E4: Soluzione | F4: Risposta squadra | G4: Esito | H4: Difficoltà percepita (1-5) | I4: Indizio dichiarato | J4: Nota di trascrizione
A5: TON|L0|1 | B5: Tontony | C5: L0 | D5: 1 | E5: Reale | F5: Reale | G5: =IF(F5="?","n.v.",IF(F5=E5,1,0)) -> 1 | H5: 1
A6: TON|L0|2 | B6: Tontony | C6: L0 | D6: 2 | E6: IA | F6: IA | G6: =IF(F6="?","n.v.",IF(F6=E6,1,0)) -> 1 | H6: 1
A7: TON|L0|3 | B7: Tontony | C7: L0 | D7: 3 | E7: IA | F7: IA | G7: =IF(F7="?","n.v.",IF(F7=E7,1,0)) -> 1 | H7: 1 | I7: Non esiste tra le vesti papali
A8: TON|L1|1 | B8: Tontony | C8: L1 | D8: 1 | E8: IA | F8: IA | G8: =IF(F8="?","n.v.",IF(F8=E8,1,0)) -> 1 | H8: 1 | I8: Muscolatura del collo estrema: se allenasse il collo sarebbe anche più largo
A9: TON|L1|2 | B9: Tontony | C9: L1 | D9: 2 | E9: Reale | F9: Reale | G9: =IF(F9="?","n.v.",IF(F9=E9,1,0)) -> 1 | H9: 2
A10: TON|L1|3 | B10: Tontony | C10: L1 | D10: 3 | E10: Reale | F10: Reale | G10: =IF(F10="?","n.v.",IF(F10=E10,1,0)) -> 1 | H10: 2
A11: TON|L2|1 | B11: Tontony | C11: L2 | D11: 1 | E11: Reale | F11: IA | G11: =IF(F11="?","n.v.",IF(F11=E11,1,0)) -> 0 | H11: 4 | I11: Differenziazioni nello sfondo secondario
A12: TON|L2|2 | B12: Tontony | C12: L2 | D12: 2 | E12: Reale | F12: Reale | G12: =IF(F12="?","n.v.",IF(F12=E12,1,0)) -> 1
A13: TON|L2|3 | B13: Tontony | C13: L2 | D13: 3 | E13: IA | F13: IA | G13: =IF(F13="?","n.v.",IF(F13=E13,1,0)) -> 1 | I13: Tratti somatici modificati
A14: TON|L3|1 | B14: Tontony | C14: L3 | D14: 1 | E14: IA | F14: IA | G14: =IF(F14="?","n.v.",IF(F14=E14,1,0)) -> 1 | H14: 5 | J14: Dal foglio aggiuntivo
A15: TON|L3|2 | B15: Tontony | C15: L3 | D15: 2 | E15: Reale | F15: Reale | G15: =IF(F15="?","n.v.",IF(F15=E15,1,0)) -> 1 | H15: 5 | J15: Dal foglio aggiuntivo
A16: TON|L3|3 | B16: Tontony | C16: L3 | D16: 3 | E16: IA | F16: IA | G16: =IF(F16="?","n.v.",IF(F16=E16,1,0)) -> 1 | H16: 5 | I16: Presenza di filtri | J16: Dal foglio aggiuntivo (corretto da No a Si)
A17: TON|L4|1 | B17: Tontony | C17: L4 | D17: 1 | E17: IA | F17: IA | G17: =IF(F17="?","n.v.",IF(F17=E17,1,0)) -> 1 | H17: 5 | I17: Contrasto elevato | J17: Corretto da No a Si nel foglio aggiuntivo
A18: TON|L4|2 | B18: Tontony | C18: L4 | D18: 2 | E18: IA | F18: ? | G18: =IF(F18="?","n.v.",IF(F18=E18,1,0)) -> n.v. | H18: 5 | I18: Saturazione dei colori | J18: Tabella: No / foglio aggiuntivo: Si - escluso dal punteggio
A19: TON|L4|3 | B19: Tontony | C19: L4 | D19: 3 | E19: IA | F19: Reale | G19: =IF(F19="?","n.v.",IF(F19=E19,1,0)) -> 0
A20: TON|L4|4 | B20: Tontony | C20: L4 | D20: 4 | E20: IA | F20: IA | G20: =IF(F20="?","n.v.",IF(F20=E20,1,0)) -> 1 | H20: 5 | I20: Persone sullo sfondo secondario irreali
A21: DIV|L0|1 | B21: Divo | C21: L0 | D21: 1 | E21: Reale | F21: Reale | G21: =IF(F21="?","n.v.",IF(F21=E21,1,0)) -> 1 | H21: 1
A22: DIV|L0|2 | B22: Divo | C22: L0 | D22: 2 | E22: IA | F22: IA | G22: =IF(F22="?","n.v.",IF(F22=E22,1,0)) -> 1 | H22: 1
A23: DIV|L0|3 | B23: Divo | C23: L0 | D23: 3 | E23: IA | F23: IA | G23: =IF(F23="?","n.v.",IF(F23=E23,1,0)) -> 1 | H23: 1
A24: DIV|L1|1 | B24: Divo | C24: L1 | D24: 1 | E24: IA | F24: IA | G24: =IF(F24="?","n.v.",IF(F24=E24,1,0)) -> 1 | H24: 1 | I24: Bambolina di porcellana
A25: DIV|L1|2 | B25: Divo | C25: L1 | D25: 2 | E25: Reale | F25: Reale | G25: =IF(F25="?","n.v.",IF(F25=E25,1,0)) -> 1 | H25: 2
A26: DIV|L1|3 | B26: Divo | C26: L1 | D26: 3 | E26: Reale | F26: Reale | G26: =IF(F26="?","n.v.",IF(F26=E26,1,0)) -> 1 | H26: 5
A27: DIV|L2|1 | B27: Divo | C27: L2 | D27: 1 | E27: Reale | F27: IA | G27: =IF(F27="?","n.v.",IF(F27=E27,1,0)) -> 0 | H27: 4 | I27: Pelle perfettissima, sfondo strano
A28: DIV|L2|2 | B28: Divo | C28: L2 | D28: 2 | E28: Reale | F28: Reale | G28: =IF(F28="?","n.v.",IF(F28=E28,1,0)) -> 1 | H28: 1
A29: DIV|L2|3 | B29: Divo | C29: L2 | D29: 3 | E29: IA | F29: IA | G29: =IF(F29="?","n.v.",IF(F29=E29,1,0)) -> 1 | H29: 2 | I29: Troppo "perfetta"
A30: DIV|L3|1 | B30: Divo | C30: L3 | D30: 1 | E30: IA | F30: IA | G30: =IF(F30="?","n.v.",IF(F30=E30,1,0)) -> 1 | H30: 4 | I30: Occhi e luce degli occhi surreale
A31: DIV|L3|2 | B31: Divo | C31: L3 | D31: 2 | E31: Reale | F31: Reale | G31: =IF(F31="?","n.v.",IF(F31=E31,1,0)) -> 1 | H31: 1
A32: DIV|L3|3 | B32: Divo | C32: L3 | D32: 3 | E32: IA | F32: IA | G32: =IF(F32="?","n.v.",IF(F32=E32,1,0)) -> 1 | H32: 2 | I32: Tratti e ombre surreali
A33: DIV|L4|1 | B33: Divo | C33: L4 | D33: 1 | E33: IA | F33: IA | G33: =IF(F33="?","n.v.",IF(F33=E33,1,0)) -> 1 | H33: 5 | I33: Mignolo strano
A34: DIV|L4|2 | B34: Divo | C34: L4 | D34: 2 | E34: IA | F34: Reale | G34: =IF(F34="?","n.v.",IF(F34=E34,1,0)) -> 0 | H34: 5
A35: DIV|L4|3 | B35: Divo | C35: L4 | D35: 3 | E35: IA | F35: Reale | G35: =IF(F35="?","n.v.",IF(F35=E35,1,0)) -> 0 | H35: 5
A36: DIV|L4|4 | B36: Divo | C36: L4 | D36: 4 | E36: IA | F36: IA | G36: =IF(F36="?","n.v.",IF(F36=E36,1,0)) -> 1 | H36: 5 | I36: Amica dietro strana
A37: BIS|L0|1 | B37: Biscotto | C37: L0 | D37: 1 | E37: Reale | F37: Reale | G37: =IF(F37="?","n.v.",IF(F37=E37,1,0)) -> 1
A38: BIS|L0|2 | B38: Biscotto | C38: L0 | D38: 2 | E38: IA | F38: IA | G38: =IF(F38="?","n.v.",IF(F38=E38,1,0)) -> 1
A39: BIS|L0|3 | B39: Biscotto | C39: L0 | D39: 3 | E39: IA | F39: IA | G39: =IF(F39="?","n.v.",IF(F39=E39,1,0)) -> 1 | I39: Come è vestito il Papa
A40: BIS|L1|1 | B40: Biscotto | C40: L1 | D40: 1 | E40: IA | F40: IA | G40: =IF(F40="?","n.v.",IF(F40=E40,1,0)) -> 1 | I40: Troppo bello, pelle perfetta
A41: BIS|L1|2 | B41: Biscotto | C41: L1 | D41: 2 | E41: Reale | F41: Reale | G41: =IF(F41="?","n.v.",IF(F41=E41,1,0)) -> 1
...

Sheet F1 Foto (matrice)
A1: Fase 1 - Matrice delle risposte (IA / Reale) per foto e squadra
A2: Verde = risposta corretta, rosso = errata. Le celle leggono il foglio 'F1 Foto (dati)'.
A4: Livello | B4: Foto | C4: Soluzione | D4: Tontony | E4: Divo | F4: Biscotto | G4: Team Pasqua | H4: Dream Team | I4: Squadre che indovinano | J4: Risposte valide | K4: % corrette | L4: Osservazione
A5: L0 | B5: 1 | C5: Reale | D5: =INDEX('F1 Foto (dati)'!$F$5:$F$84,MATCH("TON|L0|1",'F1 Foto (dati)'!$A$5:$A$84,0)) -> Reale | E5: =INDEX('F1 Foto (dati)'!$F$5:$F$84,MATCH("DIV|L0|1",'F1 Foto (dati)'!$A$5:$A$84,0)) -> Reale | F5: =INDEX('F1 Foto (dati)'!$F$5:$F$84,MATCH("BIS|L0|1",'F1 Foto (dati)'!$A$5:$A$84,0)) -> Reale | G5: =INDEX('F1 Foto (dati)'!$F$5:$F$84,MATCH("PAS|L0|1",'F1 Foto (dati)'!$A$5:$A$84,0)) -> Reale | H5: =INDEX('F1 Foto (dati)'!$F$5:$F$84,MATCH("DRE|L0|1",'F1 Foto (dati)'!$A$5:$A$84,0)) -> Reale | I5: =COUNTIFS('F1 Foto (dati)'!$C$5:$C$84,A5,'F1 Foto (dati)'!$D$5:$D$84,B5,'F1 Foto (dati)'!$G$5:$G$84,1) -> 5 | J5: =COUNTIFS('F1 Foto (dati)'!$C$5:$C$84,A5,'F1 Foto (dati)'!$D$5:$D$84,B5,'F1 Foto (dati)'!$G$5:$G$84,"<>n.v.") -> 5 | K5: =IF(J5=0,0,I5/J5) -> 1
A6: L0 | B6: 2 | C6: IA | D6: =INDEX('F1 Foto (dati)'!$F$5:$F$84,MATCH("TON|L0|2",'F1 Foto (dati)'!$A$5:$A$84,0)) -> IA | E6: =INDEX('F1 Foto (dati)'!$F$5:$F$84,MATCH("DIV|L0|2",'F1 Foto (dati)'!$A$5:$A$84,0)) -> IA | F6: =INDEX('F1 Foto (dati)'!$F$5:$F$84,MATCH("BIS|L0|2",'F1 Foto (dati)'!$A$5:$A$84,0)) -> IA | G6: =INDEX('F1 Foto (dati)'!$F$5:$F$84,MATCH("PAS|L0|2",'F1 Foto (dati)'!$A$5:$A$84,0)) -> IA | H6: =INDEX('F1 Foto (dati)'!$F$5:$F$84,MATCH("DRE|L0|2",'F1 Foto (dati)'!$A$5:$A$84,0)) -> IA | I6: =COUNTIFS('F1 Foto (dati)'!$C$5:$C$84,A6,'F1 Foto (dati)'!$D$5:$D$84,B6,'F1 Foto (dati)'!$G$5:$G$84,1) -> 5 | J6: =COUNTIFS('F1 Foto (dati)'!$C$5:$C$84,A6,'F1 Foto (dati)'!$D$5:$D$84,B6,'F1 Foto (dati)'!$G$5:$G$84,"<>n.v.") -> 5 | K6: =IF(J6=0,0,I6/J6) -> 1
A7: L0 | B7: 3 | C7: IA | D7: =INDEX('F1 Foto (dati)'!$F$5:$F$84,MATCH("TON|L0|3",'F1 Foto (dati)'!$A$5:$A$84,0)) -> IA | E7: =INDEX('F1 Foto (dati)'!$F$5:$F$84,MATCH("DIV|L0|3",'F1 Foto (dati)'!$A$5:$A$84,0)) -> IA | F7: =INDEX('F1 Foto (dati)'!$F$5:$F$84,MATCH("BIS|L0|3",'F1 Foto (dati)'!$A$5:$A$84,0)) -> IA | G7: =INDEX('F1 Foto (dati)'!$F$5:$F$84,MATCH("PAS|L0|3",'F1 Foto (dati)'!$A$5:$A$84,0)) -> IA | H7: =INDEX('F1 Foto (dati)'!$F$5:$F$84,MATCH("DRE|L0|3",'F1 Foto (dati)'!$A$5:$A$84,0)) -> IA | I7: =COUNTIFS('F1 Foto (dati)'!$C$5:$C$84,A7,'F1 Foto (dati)'!$D$5:$D$84,B7,'F1 Foto (dati)'!$G$5:$G$84,1) -> 5 | J7: =COUNTIFS('F1 Foto (dati)'!$C$5:$C$84,A7,'F1 Foto (dati)'!$D$5:$D$84,B7,'F1 Foto (dati)'!$G$5:$G$84,"<>n.v.") -> 5 | K7: =IF(J7=0,0,I7/J7) -> 1
A8: L1 | B8: 1 | C8: IA | D8: =INDEX('F1 Foto (dati)'!$F$5:$F$84,MATCH("TON|L1|1",'F1 Foto (dati)'!$A$5:$A$84,0)) -> IA | E8: =INDEX('F1 Foto (dati)'!$F$5:$F$84,MATCH("DIV|L1|1",'F1 Foto (dati)'!$A$5:$A$84,0)) -> IA | F8: =INDEX('F1 Foto (dati)'!$F$5:$F$84,MATCH("BIS|L1|1",'F1 Foto (dati)'!$A$5:$A$84,0)) -> IA | G8: =INDEX('F1 Foto (dati)'!$F$5:$F$84,MATCH("PAS|L1|1",'F1 Foto (dati)'!$A$5:$A$84,0)) -> IA | H8: =INDEX('F1 Foto (dati)'!$F$5:$F$84,MATCH("DRE|L1|1",'F1 Foto (dati)'!$A$5:$A$84,0)) -> IA | I8: =COUNTIFS('F1 Foto (dati)'!$C$5:$C$84,A8,'F1 Foto (dati)'!$D$5:$D$84,B8,'F1 Foto (dati)'!$G$5:$G$84,1) -> 5 | J8: =COUNTIFS('F1 Foto (dati)'!$C$5:$C$84,A8,'F1 Foto (dati)'!$D$5:$D$84,B8,'F1 Foto (dati)'!$G$5:$G$84,"<>n.v.") -> 5 | K8: =IF(J8=0,0,I8/J8) -> 1
A9: L1 | B9: 2 | C9: Reale | D9: =INDEX('F1 Foto (dati)'!$F$5:$F$84,MATCH("TON|L1|2",'F1 Foto (dati)'!$A$5:$A$84,0)) -> Reale | E9: =INDEX('F1 Foto (dati)'!$F$5:$F$84,MATCH("DIV|L1|2",'F1 Foto (dati)'!$A$5:$A$84,0)) -> Reale | F9: =INDEX('F1 Foto (dati)'!$F$5:$F$84,MATCH("BIS|L1|2",'F1 Foto (dati)'!$A$5:$A$84,0)) -> Reale | G9: =INDEX('F1 Foto (dati)'!$F$5:$F$84,MATCH("PAS|L1|2",'F1 Foto (dati)'!$A$5:$A$84,0)) -> Reale | H9: =INDEX('F1 Foto (dati)'!$F$5:$F$84,MATCH("DRE|L1|2",'F1 Foto (dati)'!$A$5:$A$84,0)) -> Reale | I9: =COUNTIFS('F1 Foto (dati)'!$C$5:$C$84,A9,'F1 Foto (dati)'!$D$5:$D$84,B9,'F1 Foto (dati)'!$G$5:$G$84,1) -> 5 | J9: =COUNTIFS('F1 Foto (dati)'!$C$5:$C$84,A9,'F1 Foto (dati)'!$D$5:$D$84,B9,'F1 Foto (dati)'!$G$5:$G$84,"<>n.v.") -> 5 | K9: =IF(J9=0,0,I9/J9) -> 1
A10: L1 | B10: 3 | C10: Reale | D10: =INDEX('F1 Foto (dati)'!$F$5:$F$84,MATCH("TON|L1|3",'F1 Foto (dati)'!$A$5:$A$84,0)) -> Reale | E10: =INDEX('F1 Foto (dati)'!$F$5:$F$84,MATCH("DIV|L1|3",'F1 Foto (dati)'!$A$5:$A$84,0)) -> Reale | F10: =INDEX('F1 Foto (dati)'!$F$5:$F$84,MATCH("BIS|L1|3",'F1 Foto (dati)'!$A$5:$A$84,0)) -> IA | G10: =INDEX('F1 Foto (dati)'!$F$5:$F$84,MATCH("PAS|L1|3",'F1 Foto (dati)'!$A$5:$A$84,0)) -> IA | H10: =INDEX('F1 Foto (dati)'!$F$5:$F$84,MATCH("DRE|L1|3",'F1 Foto (dati)'!$A$5:$A$84,0)) -> Reale | I10: =COUNTIFS('F1 Foto (dati)'!$C$5:$C$84,A10,'F1 Foto (dati)'!$D$5:$D$84,B10,'F1 Foto (dati)'!$G$5:$G$84,1) -> 3 | J10: =COUNTIFS('F1 Foto (dati)'!$C$5:$C$84,A10,'F1 Foto (dati)'!$D$5:$D$84,B10,'F1 Foto (dati)'!$G$5:$G$84,"<>n.v.") -> 5 | K10: =IF(J10=0,0,I10/J10) -> 0.6 | L10: Foto reale ma 'ritoccata': 2 squadre la segnano come IA (BIS, PAS)
A11: L2 | B11: 1 | C11: Reale | D11: =INDEX('F1 Foto (dati)'!$F$5:$F$84,MATCH("TON|L2|1",'F1 Foto (dati)'!$A$5:$A$84,0)) -> IA | E11: =INDEX('F1 Foto (dati)'!$F$5:$F$84,MATCH("DIV|L2|1",'F1 Foto (dati)'!$A$5:$A$84,0)) -> IA | F11: =INDEX('F1 Foto (dati)'!$F$5:$F$84,MATCH("BIS|L2|1",'F1 Foto (dati)'!$A$5:$A$84,0)) -> Reale | G11: =INDEX('F1 Foto (dati)'!$F$5:$F$84,MATCH("PAS|L2|1",'F1 Foto (dati)'!$A$5:$A$84,0)) -> IA | H11: =INDEX('F1 Foto (dati)'!$F$5:$F$84,MATCH("DRE|L2|1",'F1 Foto (dati)'!$A$5:$A$84,0)) -> Reale | I11: =COUNTIFS('F1 Foto (dati)'!$C$5:$C$84,A11,'F1 Foto (dati)'!$D$5:$D$84,B11,'F1 Foto (dati)'!$G$5:$G$84,1) -> 2 | J11: =COUNTIFS('F1 Foto (dati)'!$C$5:$C$84,A11,'F1 Foto (dati)'!$D$5:$D$84,B11,'F1 Foto (dati)'!$G$5:$G$84,"<>n.v.") -> 5 | K11: =IF(J11=0,0,I11/J11) -> 0.4 | L11: Foto reale giudicata IA da 3 squadre per sfondo, pelle o mano: l'indizio 'troppo perfetto' genera falsi allarmi
A12: L2 | B12: 2 | C12: Reale | D12: =INDEX('F1 Foto (dati)'!$F$5:$F$84,MATCH("TON|L2|2",'F1 Foto (dati)'!$A$5:$A$84,0)) -> Reale | E12: =INDEX('F1 Foto (dati)'!$F$5:$F$84,MATCH("DIV|L2|2",'F1 Foto (dati)'!$A$5:$A$84,0)) -> Reale | F12: =INDEX('F1 Foto (dati)'!$F$5:$F$84,MATCH("BIS|L2|2",'F1 Foto (dati)'!$A$5:$A$84,0)) -> Reale | G12: =INDEX('F1 Foto (dati)'!$F$5:$F$84,MATCH("PAS|L2|2",'F1 Foto (dati)'!$A$5:$A$84,0)) -> Reale | H12: =INDEX('F1 Foto (dati)'!$F$5:$F$84,MATCH("DRE|L2|2",'F1 Foto (dati)'!$A$5:$A$84,0)) -> Reale | I12: =COUNTIFS('F1 Foto (dati)'!$C$5:$C$84,A12,'F1 Foto (dati)'!$D$5:$D$84,B12,'F1 Foto (dati)'!$G$5:$G$84,1) -> 5 | J12: =COUNTIFS('F1 Foto (dati)'!$C$5:$C$84,A12,'F1 Foto (dati)'!$D$5:$D$84,B12,'F1 Foto (dati)'!$G$5:$G$84,"<>n.v.") -> 5 | K12: =IF(J12=0,0,I12/J12) -> 1
A13: L2 | B13: 3 | C13: IA | D13: =INDEX('F1 Foto (dati)'!$F$5:$F$84,MATCH("TON|L2|3",'F1 Foto (dati)'!$A$5:$A$84,0)) -> IA | E13: =INDEX('F1 Foto (dati)'!$F$5:$F$84,MATCH("DIV|L2|3",'F1 Foto (dati)'!$A$5:$A$84,0)) -> IA | F13: =INDEX('F1 Foto (dati)'!$F$5:$F$84,MATCH("BIS|L2|3",'F1 Foto (dati)'!$A$5:$A$84,0)) -> IA | G13: =INDEX('F1 Foto (dati)'!$F$5:$F$84,MATCH("PAS|L2|3",'F1 Foto (dati)'!$A$5:$A$84,0)) -> IA | H13: =INDEX('F1 Foto (dati)'!$F$5:$F$84,MATCH("DRE|L2|3",'F1 Foto (dati)'!$A$5:$A$84,0)) -> IA | I13: =COUNTIFS('F1 Foto (dati)'!$C$5:$C$84,A13,'F1 Foto (dati)'!$D$5:$D$84,B13,'F1 Foto (dati)'!$G$5:$G$84,1) -> 5 | J13: =COUNTIFS('F1 Foto (dati)'!$C$5:$C$84,A13,'F1 Foto (dati)'!$D$5:$D$84,B13,'F1 Foto (dati)'!$G$5:$G$84,"<>n.v.") -> 5 | K13: =IF(J13=0,0,I13/J13) -> 1
A14: L3 | B14: 1 | C14: IA | D14: =INDEX('F1 Foto (dati)'!$F$5:$F$84,MATCH("TON|L3|1",'F1 Foto (dati)'!$A$5:$A$84,0)) -> IA | E14: =INDEX('F1 Foto (dati)'!$F$5:$F$84,MATCH("DIV|L3|1",'F1 Foto (dati)'!$A$5:$A$84,0)) -> IA | F14: =INDEX('F1 Foto (dati)'!$F$5:$F$84,MATCH("BIS|L3|1",'F1 Foto (dati)'!$A$5:$A$84,0)) -> IA | G14: =INDEX('F1 Foto (dati)'!$F$5:$F$84,MATCH("PAS|L3|1",'F1 Foto (dati)'!$A$5:$A$84,0)) -> IA | H14: =INDEX('F1 Foto (dati)'!$F$5:$F$84,MATCH("DRE|L3|1",'F1 Foto (dati)'!$A$5:$A$84,0)) -> Reale | I14: =COUNTIFS('F1 Foto (dati)'!$C$5:$C$84,A14,'F1 Foto (dati)'!$D$5:$D$84,B14,'F1 Foto (dati)'!$G$5:$G$84,1) -> 4 | J14: =COUNTIFS('F1 Foto (dati)'!$C$5:$C$84,A14,'F1 Foto (dati)'!$D$5:$D$84,B14,'F1 Foto (dati)'!$G$5:$G$84,"<>n.v.") -> 5 | K14: =IF(J14=0,0,I14/J14) -> 0.8
A15: L3 | B15: 2 | C15: Reale | D15: =INDEX('F1 Foto (dati)'!$F$5:$F$84,MATCH("TON|L3|2",'F1 Foto (dati)'!$A$5:$A$84,0)) -> Reale | E15: =INDEX('F1 Foto (dati)'!$F$5:$F$84,MATCH("DIV|L3|2",'F1 Foto (dati)'!$A$5:$A$84,0)) -> Reale | F15: =INDEX('F1 Foto (dati)'!$F$5:$F$84,MATCH("BIS|L3|2",'F1 Foto (dati)'!$A$5:$A$84,0)) -> Reale | G15: =INDEX('F1 Foto (dati)'!$F$5:$F$84,MATCH("PAS|L3|2",'F1 Foto (dati)'!$A$5:$A$84,0)) -> Reale | H15: =INDEX('F1 Foto (dati)'!$F$5:$F$84,MATCH("DRE|L3|2",'F1 Foto (dati)'!$A$5:$A$84,0)) -> Reale | I15: =COUNTIFS('F1 Foto (dati)'!$C$5:$C$84,A15,'F1 Foto (dati)'!$D$5:$D$84,B15,'F1 Foto (dati)'!$G$5:$G$84,1) -> 5 | J15: =COUNTIFS('F1 Foto (dati)'!$C$5:$C$84,A15,'F1 Foto (dati)'!$D$5:$D$84,B15,'F1 Foto (dati)'!$G$5:$G$84,"<>n.v.") -> 5 | K15: =IF(J15=0,0,I15/J15) -> 1
A16: L3 | B16: 3 | C16: IA | D16: =INDEX('F1 Foto (dati)'!$F$5:$F$84,MATCH("TON|L3|3",'F1 Foto (dati)'!$A$5:$A$84,0)) -> IA | E16: =INDEX('F1 Foto (dati)'!$F$5:$F$84,MATCH("DIV|L3|3",'F1 Foto (dati)'!$A$5:$A$84,0)) -> IA | F16: =INDEX('F1 Foto (dati)'!$F$5:$F$84,MATCH("BIS|L3|3",'F1 Foto (dati)'!$A$5:$A$84,0)) -> Reale | G16: =INDEX('F1 Foto (dati)'!$F$5:$F$84,MATCH("PAS|L3|3",'F1 Foto (dati)'!$A$5:$A$84,0)) -> IA | H16: =INDEX('F1 Foto (dati)'!$F$5:$F$84,MATCH("DRE|L3|3",'F1 Foto (dati)'!$A$5:$A$84,0)) -> ? | I16: =COUNTIFS('F1 Foto (dati)'!$C$5:$C$84,A16,'F1 Foto (dati)'!$D$5:$D$84,B16,'F1 Foto (dati)'!$G$5:$G$84,1) -> 3 | J16: =COUNTIFS('F1 Foto (dati)'!$C$5:$C$84,A16,'F1 Foto (dati)'!$D$5:$D$84,B16,'F1 Foto (dati)'!$G$5:$G$84,"<>n.v.") -> 4 | K16: =IF(J16=0,0,I16/J16) -> 0.75 | L16: BIS la crede reale perché 'la faccia sembra una conosciuta': la familiarità abbassa la guardia
A17: L4 | B17: 1 | C17: IA | D17: =INDEX('F1 Foto (dati)'!$F$5:$F$84,MATCH("TON|L4|1",'F1 Foto (dati)'!$A$5:$A$84,0)) -> IA | E17: =INDEX('F1 Foto (dati)'!$F$5:$F$84,MATCH("DIV|L4|1",'F1 Foto (dati)'!$A$5:$A$84,0)) -> IA | F17: =INDEX('F1 Foto (dati)'!$F$5:$F$84,MATCH("BIS|L4|1",'F1 Foto (dati)'!$A$5:$A$84,0)) -> IA | G17: =INDEX('F1 Foto (dati)'!$F$5:$F$84,MATCH("PAS|L4|1",'F1 Foto (dati)'!$A$5:$A$84,0)) -> IA | H17: =INDEX('F1 Foto (dati)'!$F$5:$F$84,MATCH("DRE|L4|1",'F1 Foto (dati)'!$A$5:$A$84,0)) -> IA | I17: =COUNTIFS('F1 Foto (dati)'!$C$5:$C$84,A17,'F1 Foto (dati)'!$D$5:$D$84,B17,'F1 Foto (dati)'!$G$5:$G$84,1) -> 5 | J17: =COUNTIFS('F1 Foto (dati)'!$C$5:$C$84,A17,'F1 Foto (dati)'!$D$5:$D$84,B17,'F1 Foto (dati)'!$G$5:$G$84,"<>n.v.") -> 5 | K17: =IF(J17=0,0,I17/J17) -> 1
A18: L4 | B18: 2 | C18: IA | D18: =INDEX('F1 Foto (dati)'!$F$5:$F$84,MATCH("TON|L4|2",'F1 Foto (dati)'!$A$5:$A$84,0)) -> ? | E18: =INDEX('F1 Foto (dati)'!$F$5:$F$84,MATCH("DIV|L4|2",'F1 Foto (dati)'!$A$5:$A$84,0)) -> Reale | F18: =INDEX('F1 Foto (dati)'!$F$5:$F$84,MATCH("BIS|L4|2",'F1 Foto (dati)'!$A$5:$A$84,0)) -> Reale | G18: =INDEX('F1 Foto (dati)'!$F$5:$F$84,MATCH("PAS|L4|2",'F1 Foto (dati)'!$A$5:$A$84,0)) -> IA | H18: =INDEX('F1 Foto (dati)'!$F$5:$F$84,MATCH("DRE|L4|2",'F1 Foto (dati)'!$A$5:$A$84,0)) -> IA | I18: =COUNTIFS('F1 Foto (dati)'!$C$5:$C$84,A18,'F1 Foto (dati)'!$D$5:$D$84,B18,'F1 Foto (dati)'!$G$5:$G$84,1) -> 2 | J18: =COUNTIFS('F1 Foto (dati)'!$C$5:$C$84,A18,'F1 Foto (dati)'!$D$5:$D$84,B18,'F1 Foto (dati)'!$G$5:$G$84,"<>n.v.") -> 4 | K18: =IF(J18=0,0,I18/J18) -> 0.5 | L18: Divisione netta tra squadre
A19: L4 | B19: 3 | C19: IA | D19: =INDEX('F1 Foto (dati)'!$F$5:$F$84,MATCH("TON|L4|3",'F1 Foto (dati)'!$A$5:$A$84,0)) -> Reale | E19: =INDEX('F1 Foto (dati)'!$F$5:$F$84,MATCH("DIV|L4|3",'F1 Foto (dati)'!$A$5:$A$84,0)) -> Reale | F19: =INDEX('F1 Foto (dati)'!$F$5:$F$84,MATCH("BIS|L4|3",'F1 Foto (dati)'!$A$5:$A$84,0)) -> Reale | G19: =INDEX('F1 Foto (dati)'!$F$5:$F$84,MATCH("PAS|L4|3",'F1 Foto (dati)'!$A$5:$A$84,0)) -> Reale | H19: =INDEX('F1 Foto (dati)'!$F$5:$F$84,MATCH("DRE|L4|3",'F1 Foto (dati)'!$A$5:$A$84,0)) -> Reale | I19: =COUNTIFS('F1 Foto (dati)'!$C$5:$C$84,A19,'F1 Foto (dati)'!$D$5:$D$84,B19,'F1 Foto (dati)'!$G$5:$G$84,1) -> 0 | J19: =COUNTIFS('F1 Foto (dati)'!$C$5:$C$84,A19,'F1 Foto (dati)'!$D$5:$D$84,B19,'F1 Foto (dati)'!$G$5:$G$84,"<>n.v.") -> 5 | K19: =IF(J19=0,0,I19/J19) -> 0 | L19: Nessuna squadra la riconosce come IA. PAS: "non ci aspettavamo che fosse vera"
A20: L4 | B20: 4 | C20: IA | D20: =INDEX('F1 Foto (dati)'!$F$5:$F$84,MATCH("TON|L4|4",'F1 Foto (dati)'!$A$5:$A$84,0)) -> IA | E20: =INDEX('F1 Foto (dati)'!$F$5:$F$84,MATCH("DIV|L4|4",'F1 Foto (dati)'!$A$5:$A$84,0)) -> IA | F20: =INDEX('F1 Foto (dati)'!$F$5:$F$84,MATCH("BIS|L4|4",'F1 Foto (dati)'!$A$5:$A$84,0)) -> Reale | G20: =INDEX('F1 Foto (dati)'!$F$5:$F$84,MATCH("PAS|L4|4",'F1 Foto (dati)'!$A$5:$A$84,0)) -> IA | H20: =INDEX('F1 Foto (dati)'!$F$5:$F$84,MATCH("DRE|L4|4",'F1 Foto (dati)'!$A$5:$A$84,0)) -> Reale | I20: =COUNTIFS('F1 Foto (dati)'!$C$5:$C$84,A20,'F1 Foto (dati)'!$D$5:$D$84,B20,'F1 Foto (dati)'!$G$5:$G$84,1) -> 3 | J20: =COUNTIFS('F1 Foto (dati)'!$C$5:$C$84,A20,'F1 Foto (dati)'!$D$5:$D$84,B20,'F1 Foto (dati)'!$G$5:$G$84,"<>n.v.") -> 5 | K20: =IF(J20=0,0,I20/J20) -> 0.6 | L20: Chi la riconosce lo fa dalle persone sullo sfondo
A22: Commenti scritti dalle squadre
A23: Tontony | B23: "Ci siamo accorti che alle volte è molto facile cadere nelle trappole dell'IA"
A24: Divo | B24: "Le iniziali erano molto semplici mentre il livello 4 era difficilissimo"
A25: Dream Team | B25: "È stato sconvolgente scoprire di non essere capaci di individuare nei livelli più avanzati le immagini create dall'IA"

Sheet F1bis Coppie
A1: Fase 1bis - Confronti: quale foto è stata generata dall'altra, e quella rimasta com'è?
A2: Soluzioni dalla presentazione: A = Foto 2 generata, Foto 1 a sua volta modificata; B = Foto 2 generata, Foto 1 autentica; C = Foto 1 generata, Foto 2 modificata
A4: Squadra | B4: Coppia | C4: Sol. foto generata | D4: Risposta | E4: Esito | F4: Sol. foto rimasta | G4: Risposta | H4: Esito | I4: Difficoltà | J4: Note / indizi
A5: Tontony | B5: A | C5: Foto 2 | D5: Foto 2 | E5: =IF(D5="","n.c.",IF(D5=C5,1,0)) -> 1 | F5: Modificata | G5: Modificata | H5: =IF(G5="","n.c.",IF(G5="?","n.v.",IF(G5=F5,1,0))) -> 1 | I5: 2 | J5: Componenti dell'auto sproporzionati
A6: Tontony | B6: B | C6: Foto 2 | D6: Foto 2 | E6: =IF(D6="","n.c.",IF(D6=C6,1,0)) -> 1 | F6: Autentica | G6: Autentica | H6: =IF(G6="","n.c.",IF(G6="?","n.v.",IF(G6=F6,1,0))) -> 1 | J6: Rossore sotto (gli occhi)
A7: Tontony | B7: C | C7: Foto 1 | D7: Foto 1 | E7: =IF(D7="","n.c.",IF(D7=C7,1,0)) -> 1 | F7: Modificata | G7: Modificata | H7: =IF(G7="","n.c.",IF(G7="?","n.v.",IF(G7=F7,1,0))) -> 1
A8: Divo | B8: A | C8: Foto 2 | D8: Foto 2 | E8: =IF(D8="","n.c.",IF(D8=C8,1,0)) -> 1 | F8: Modificata | G8: Autentica | H8: =IF(G8="","n.c.",IF(G8="?","n.v.",IF(G8=F8,1,0))) -> 0 | I8: 4 | J8: "ops"
A9: Divo | B9: B | C9: Foto 2 | D9: Foto 2 | E9: =IF(D9="","n.c.",IF(D9=C9,1,0)) -> 1 | F9: Autentica | G9: Autentica | H9: =IF(G9="","n.c.",IF(G9="?","n.v.",IF(G9=F9,1,0))) -> 1
A10: Divo | B10: C | C10: Foto 1 | E10: =IF(D10="","n.c.",IF(D10=C10,1,0)) -> n.c. | F10: Modificata | G10: Modificata | H10: =IF(G10="","n.c.",IF(G10="?","n.v.",IF(G10=F10,1,0))) -> 1 | J10: Foto generata non indicata
A11: Biscotto | B11: A | C11: Foto 2 | D11: Foto 2 | E11: =IF(D11="","n.c.",IF(D11=C11,1,0)) -> 1 | F11: Modificata | G11: Modificata | H11: =IF(G11="","n.c.",IF(G11="?","n.v.",IF(G11=F11,1,0))) -> 1
A12: Biscotto | B12: B | C12: Foto 2 | D12: Foto 2 | E12: =IF(D12="","n.c.",IF(D12=C12,1,0)) -> 1 | F12: Autentica | G12: Modificata | H12: =IF(G12="","n.c.",IF(G12="?","n.v.",IF(G12=F12,1,0))) -> 0
A13: Biscotto | B13: C | C13: Foto 1 | E13: =IF(D13="","n.c.",IF(D13=C13,1,0)) -> n.c. | F13: Modificata | H13: =IF(G13="","n.c.",IF(G13="?","n.v.",IF(G13=F13,1,0))) -> n.c. | J13: Non compilata
A14: Team Pasqua | B14: A | C14: Foto 2 | D14: Foto 2 | E14: =IF(D14="","n.c.",IF(D14=C14,1,0)) -> 1 | F14: Modificata | G14: Modificata | H14: =IF(G14="","n.c.",IF(G14="?","n.v.",IF(G14=F14,1,0))) -> 1 | J14: Troppo perfetta
A15: Team Pasqua | B15: B | C15: Foto 2 | D15: Foto 2 | E15: =IF(D15="","n.c.",IF(D15=C15,1,0)) -> 1 | F15: Autentica | G15: ? | H15: =IF(G15="","n.c.",IF(G15="?","n.v.",IF(G15=F15,1,0))) -> n.v. | J15: Autentica e Modificata entrambe barrate
A16: Team Pasqua | B16: C | C16: Foto 1 | E16: =IF(D16="","n.c.",IF(D16=C16,1,0)) -> n.c. | F16: Modificata | H16: =IF(G16="","n.c.",IF(G16="?","n.v.",IF(G16=F16,1,0))) -> n.c. | J16: Non compilata
A17: Dream Team | B17: A | C17: Foto 2 | D17: Foto 2 | E17: =IF(D17="","n.c.",IF(D17=C17,1,0)) -> 1 | F17: Modificata | G17: Autentica | H17: =IF(G17="","n.c.",IF(G17="?","n.v.",IF(G17=F17,1,0))) -> 0 | I17: 2
A18: Dream Team | B18: B | C18: Foto 2 | D18: Foto 2 | E18: =IF(D18="","n.c.",IF(D18=C18,1,0)) -> 1 | F18: Autentica | G18: Autentica | H18: =IF(G18="","n.c.",IF(G18="?","n.v.",IF(G18=F18,1,0))) -> 1 | I18: 4
A19: Dream Team | B19: C | C19: Foto 1 | D19: Foto 1 | E19: =IF(D19="","n.c.",IF(D19=C19,1,0)) -> 1 | F19: Modificata | G19: Modificata | H19: =IF(G19="","n.c.",IF(G19="?","n.v.",IF(G19=F19,1,0))) -> 1 | I19: 4
A21: Coppia | C21: Foto generata: corrette | D21: su compilate | F21: Foto rimasta: corrette | G21: su valide | J21: Lettura
A22: A | C22: =COUNTIFS($B$5:$B$19,A22,$E$5:$E$19,1) -> 5 | D22: =COUNTIFS($B$5:$B$19,A22,$E$5:$E$19,"<>n.c.") -> 5 | F22: =COUNTIFS($B$5:$B$19,A22,$H$5:$H$19,1) -> 3 | G22: =COUNTIFS($B$5:$B$19,A22,$H$5:$H$19,"<>n.c.",$H$5:$H$19,"<>n.v.") -> 5 | J22: Tutti trovano la foto generata, ma Divo e Dream Team credono autentica la foto di partenza, che era già stata modificata: nessuno si aspetta una doppia manipolazione.
A23: B | C23: =COUNTIFS($B$5:$B$19,A23,$E$5:$E$19,1) -> 5 | D23: =COUNTIFS($B$5:$B$19,A23,$E$5:$E$19,"<>n.c.") -> 5 | F23: =COUNTIFS($B$5:$B$19,A23,$H$5:$H$19,1) -> 3 | G23: =COUNTIFS($B$5:$B$19,A23,$H$5:$H$19,"<>n.c.",$H$5:$H$19,"<>n.v.") -> 4 | J23: Foto generata trovata da tutti; Biscotto pensa che anche l'originale sia modificata (eccesso di sospetto).
A24: C | C24: =COUNTIFS($B$5:$B$19,A24,$E$5:$E$19,1) -> 2 | D24: =COUNTIFS($B$5:$B$19,A24,$E$5:$E$19,"<>n.c.") -> 2 | F24: =COUNTIFS($B$5:$B$19,A24,$H$5:$H$19,1) -> 3 | G24: =COUNTIFS($B$5:$B$19,A24,$H$5:$H$19,"<>n.c.",$H$5:$H$19,"<>n.v.") -> 3 | J24: Biscotto e Team Pasqua non la compilano, Divo solo in parte; chi risponde lo fa correttamente.

Sheet Indizi usati
A1: Su cosa si basano per dire 'è fatta con l'IA'
A2: Ogni riga è un indizio scritto in una scheda. Esito = la risposta a cui l'indizio ha portato era giusta (1) o sbagliata (0)
A4: Categoria | B4: Squadra | C4: Riferimento | D4: Indizio scritto | E4: Risposta data | F4: Soluzione | G4: Esito
A5: Contesto implausibile | B5: Tontony | C5: F1-L0-F3 | D5: Non esiste tra le vesti papali | E5: IA | F5: IA | G5: =IF(E5="?","n.v.",IF(E5=F5,1,0)) -> 1
A6: Anatomia (mani, dita, collo) | B6: Tontony | C6: F1-L1-F1 | D6: Muscolatura del collo estrema: se allenasse il collo sarebbe anche più largo | E6: IA | F6: IA | G6: =IF(E6="?","n.v.",IF(E6=F6,1,0)) -> 1
A7: Sfondo e persone sullo sfondo | B7: Tontony | C7: F1-L2-F1 | D7: Differenziazioni nello sfondo secondario | E7: IA | F7: Reale | G7: =IF(E7="?","n.v.",IF(E7=F7,1,0)) -> 0
A8: Tratti del volto alterati | B8: Tontony | C8: F1-L2-F3 | D8: Tratti somatici modificati | E8: IA | F8: IA | G8: =IF(E8="?","n.v.",IF(E8=F8,1,0)) -> 1
A9: Filtri, colori, ritocco | B9: Tontony | C9: F1-L3-F3 | D9: Presenza di filtri | E9: IA | F9: IA | G9: =IF(E9="?","n.v.",IF(E9=F9,1,0)) -> 1
A10: Filtri, colori, ritocco | B10: Tontony | C10: F1-L4-F1 | D10: Contrasto elevato | E10: IA | F10: IA | G10: =IF(E10="?","n.v.",IF(E10=F10,1,0)) -> 1
A11: Filtri, colori, ritocco | B11: Tontony | C11: F1-L4-F2 | D11: Saturazione dei colori | E11: ? | F11: IA | G11: =IF(E11="?","n.v.",IF(E11=F11,1,0)) -> n.v.
A12: Sfondo e persone sullo sfondo | B12: Tontony | C12: F1-L4-F4 | D12: Persone sullo sfondo secondario irreali | E12: IA | F12: IA | G12: =IF(E12="?","n.v.",IF(E12=F12,1,0)) -> 1
A13: Pelle/volto 'troppo perfetti' | B13: Divo | C13: F1-L1-F1 | D13: Bambolina di porcellana | E13: IA | F13: IA | G13: =IF(E13="?","n.v.",IF(E13=F13,1,0)) -> 1
A14: Pelle/volto 'troppo perfetti' | B14: Divo | C14: F1-L2-F1 | D14: Pelle perfettissima, sfondo strano | E14: IA | F14: Reale | G14: =IF(E14="?","n.v.",IF(E14=F14,1,0)) -> 0
A15: Sfondo e persone sullo sfondo | B15: Divo | C15: F1-L2-F1 | D15: Pelle perfettissima, sfondo strano | E15: IA | F15: Reale | G15: =IF(E15="?","n.v.",IF(E15=F15,1,0)) -> 0
A16: Pelle/volto 'troppo perfetti' | B16: Divo | C16: F1-L2-F3 | D16: Troppo "perfetta" | E16: IA | F16: IA | G16: =IF(E16="?","n.v.",IF(E16=F16,1,0)) -> 1
... A46: Sfondo e persone sullo sfondo | B46: Dream Team | C46: F1-L4-F2 | D46: Sfondo | E46: IA | F46: IA | G46: =IF(E46="?","n.v.",IF(E46=F46,1,0)) -> 1
A47: Oggetti deformati o fusi | B47: Tontony | C47: F1bis-A | D47: Componenti dell'auto sproporzionati | E47: Foto 2 | F47: Foto 2 | G47: =IF(E47=F47,1,0) -> 1
A48: Tratti del volto alterati | B48: Tontony | C48: F1bis-B | D48: Rossore sotto (gli occhi) | E48: Foto 2 | F48: Foto 2 | G48: =IF(E48=F48,1,0) -> 1
A49: Pelle/volto 'troppo perfetti' | B49: Team Pasqua | C49: F1bis-A | D49: Troppo perfetta | E49: Foto 2 | F49: Foto 2 | G49: =IF(E49=F49,1,0) -> 1
A51: Riepilogo per categoria
A52: Categoria | B52: Citazioni | C52: Squadre che la usano | D52: Portano alla risposta giusta | E52: Affidabilità | H52: Lettura
A53: Pelle/volto 'troppo perfetti' | B53: =COUNTIF($A$5:$A$49,A53) -> 10 | C53: Biscotto, Divo, Dream Team, Team Pasqua | D53: =COUNTIFS($A$5:$A$49,A53,$G$5:$G$49,1) -> 9 | E53: =IFERROR(D53/COUNTIFS($A$5:$A$49,A53,$G$5:$G$49,"<>n.v."),0) -> 0.9 | H53: L'indizio più condiviso. Funziona sulle foto facili ma genera anche falsi allarmi su foto reali (F1-L2-F1).
A54: Sfondo e persone sullo sfondo | B54: =COUNTIF($A$5:$A$49,A54) -> 10 | C54: Biscotto, Divo, Dream Team, Team Pasqua, Tontony | D54: =COUNTIFS($A$5:$A$49,A54,$G$5:$G$49,1) -> 7 | E54: =IFERROR(D54/COUNTIFS($A$5:$A$49,A54,$G$5:$G$49,"<>n.v."),0) -> 0.7 | H54: Il più usato in assoluto e il più utile sui livelli difficili (persone sullo sfondo), ma uno 'sfondo dettagliato' viene letto anche come prova di realtà.
A55: Anatomia (mani, dita, collo) | B55: =COUNTIF($A$5:$A$49,A55) -> 4 | C55: Biscotto, Divo, Team Pasqua, Tontony | D55: =COUNTIFS($A$5:$A$49,A55,$G$5:$G$49,1) -> 3 | E55: =IFERROR(D55/COUNTIFS($A$5:$A$49,A55,$G$5:$G$49,"<>n.v."),0) -> 0.75 | H55: Utile (mignolo, collo) ma porta a errori quando un dettaglio reale sembra strano (la mano in F1-L2-F1).
A56: Luce, occhi, ombre | B56: =COUNTIF($A$5:$A$49,A56) -> 3 | C56: Divo, Team Pasqua | D56: =COUNTIFS($A$5:$A$49,A56,$G$5:$G$49,1) -> 3 | E56: =IFERROR(D56/COUNTIFS($A$5:$A$49,A56,$G$5:$G$49,"<>n.v."),0) -> 1 | H56: Usato poco, ma sempre con esito corretto.
A57: Filtri, colori, ritocco | B57: =COUNTIF($A$5:$A$49,A57) -> 7 | C57: Biscotto, Dream Team, Team Pasqua, Tontony | D57: =COUNTIFS($A$5:$A$49,A57,$G$5:$G$49,1) -> 3 | E57: =IFERROR(D57/COUNTIFS($A$5:$A$49,A57,$G$5:$G$49,"<>n.v."),0) -> 0.6 | H57: Confonde 'ritoccata' con 'generata': le foto reali con filtri vengono scambiate per IA.
A58: Oggetti deformati o fusi | B58: =COUNTIF($A$5:$A$49,A58) -> 4 | C58: Dream Team, Team Pasqua, Tontony | D58: =COUNTIFS($A$5:$A$49,A58,$G$5:$G$49,1) -> 4 | E58: =IFERROR(D58/COUNTIFS($A$5:$A$49,A58,$G$5:$G$49,"<>n.v."),0) -> 1 | H58: Indizio raro ma preciso (porta storta, auto sproporzionata).
A59: Contesto implausibile | B59: =COUNTIF($A$5:$A$49,A59) -> 3 | C59: Biscotto, Dream Team, Tontony | D59: =COUNTIFS($A$5:$A$49,A59,$G$5:$G$49,1) -> 3 | E59: =IFERROR(D59/COUNTIFS($A$5:$A$49,A59,$G$5:$G$49,"<>n.v."),0) -> 1 | H59: Funziona solo sul caso famoso (il Papa): utile per le foto virali, inutile sui selfie.
A60: Familiarità / somiglianza | B60: =COUNTIF($A$5:$A$49,A60) -> 2 | C60: Biscotto, Team Pasqua | D60: =COUNTIFS($A$5:$A$49,A60,$G$5:$G$49,1) -> 1 | E60: =IFERROR(D60/COUNTIFS($A$5:$A$49,A60,$G$5:$G$49,"<>n.v."),0) -> 0.5 | H60: Pericoloso: un volto che 'sembra conosciuto' rende la foto più credibile.
A61: Tratti del volto alterati | B61: =COUNTIF($A$5:$A$49,A61) -> 2 | C61: Tontony | D61: =COUNTIFS($A$5:$A$49,A61,$G$5:$G$49,1) -> 2 | E61: =IFERROR(D61/COUNTIFS($A$5:$A$49,A61,$G$5:$G$49,"<>n.v."),0) -> 1 | H61: Indizio fine, usato da una sola squadra.

Sheet F2 Chat
A1: Fase 2 - Fidarsi? Giudizio sulle chat
A2: Domanda 1 della scheda: 'Secondo voi è una chat sospetta di adescamento?' (le domande 2-3 sono state discusse a voce)
A4: Chat | B4: Tontony | C4: Divo | D4: Biscotto | E4: Team Pasqua | F4: Dream Team | G4: Sì | H4: No | I4: Non sappiamo | J4: Non compilata | K4: Consenso
A5: Chat 1 | B5: Sì | C5: No | D5: Sì | E5: Sì | F5: Sì | G5: =COUNTIF(B5:F5,"Sì") -> 4 | H5: =COUNTIF(B5:F5,"No") -> 1 | I5: =COUNTIF(B5:F5,"Non sappiamo") -> 0 | J5: =5-G5-H5-I5 -> 0 | K5: =IF(G5=5,"Unanime: sospetta",IF(G5>=(G5+H5+I5)*0.75,"Ampia maggioranza: sospetta",IF(G5>H5+I5,"Maggioranza: sospetta","Divisi / incerti"))) -> Ampia maggioranza: sospetta
A6: Chat 2 | B6: Non sappiamo | D6: Sì | F6: No | G6: =COUNTIF(B6:F6,"Sì") -> 1 | H6: =COUNTIF(B6:F6,"No") -> 1 | I6: =COUNTIF(B6:F6,"Non sappiamo") -> 1 | J6: =5-G6-H6-I6 -> 2 | K6: =IF(G6=5,"Unanime: sospetta",IF(G6>=(G6+H6+I6)*0.75,"Ampia maggioranza: sospetta",IF(G6>H6+I6,"Maggioranza: sospetta","Divisi / incerti"))) -> Divisi / incerti
A7: Chat 3 | B7: Sì | C7: Sì | D7: Sì | E7: Sì | F7: No | G7: =COUNTIF(B7:F7,"Sì") -> 4 | H7: =COUNTIF(B7:F7,"No") -> 1 | I7: =COUNTIF(B7:F7,"Non sappiamo") -> 0 | J7: =5-G7-H7-I7 -> 0 | K7: =IF(G7=5,"Unanime: sospetta",IF(G7>=(G7+H7+I7)*0.75,"Ampia maggioranza: sospetta",IF(G7>H7+I7,"Maggioranza: sospetta","Divisi / incerti"))) -> Ampia maggioranza: sospetta
A8: Chat 4 (parte 1 e 2) | B8: Sì | D8: Sì | E8: Sì | F8: Sì | G8: =COUNTIF(B8:F8,"Sì") -> 4 | H8: =COUNTIF(B8:F8,"No") -> 0 | I8: =COUNTIF(B8:F8,"Non sappiamo") -> 0 | J8: =5-G8-H8-I8 -> 1 | K8: =IF(G8=5,"Unanime: sospetta",IF(G8>=(G8+H8+I8)*0.75,"Ampia maggioranza: sospetta",IF(G8>H8+I8,"Maggioranza: sospetta","Divisi / incerti"))) -> Ampia maggioranza: sospetta
A9: Chat 5 | B9: Sì | C9: Sì | D9: Sì | E9: Sì | F9: Non sappiamo | G9: =COUNTIF(B9:F9,"Sì") -> 4 | H9: =COUNTIF(B9:F9,"No") -> 0 | I9: =COUNTIF(B9:F9,"Non sappiamo") -> 1 | J9: =5-G9-H9-I9 -> 0 | K9: =IF(G9=5,"Unanime: sospetta",IF(G9>=(G9+H9+I9)*0.75,"Ampia maggioranza: sospetta",IF(G9>H9+I9,"Maggioranza: sospetta","Divisi / incerti"))) -> Ampia maggioranza: sospetta
A11: Cosa hanno notato, chat per chat
A12: Chat | B12: Note scritte dai gruppi | F12: Osservazioni del team (codici OSS) | K12: Punti comuni / divergenze
A13: Chat 1 | B13: [CH-TON-C1] Tontony: Vittimismo finale, trucco psicologico; non rivela l'identità e fa domande sospette; risponde troppo velocemente [CH-DRE-C1] Dream Team: Domande strane, un po' da stalker; chiede foto; evita i problemi | F13: [OSS-01] Chat percepita come normale, forse "pressa un po' troppo" [OSS-02] Notano la schermata centrale: controllare il telefono e inventare scuse [OSS-03] Lo bloccherebbero [OSS-04] L'ultima schermata, gli ultimi messaggi sono i peggiori (escalation) [OSS-05] Molti capiscono che la chat 1 è pericolosa e discutono sia dei messaggi sia delle risposte | K13: COMUNE: riconoscono l'escalation finale e la richiesta di nascondere/controllare il telefono; reazione tipica: bloccare. DIVERGENZA: Divo la giudica non sospetta e un'osservazione la descrive come 'chat normale': i segnali iniziali sono deboli e vengono notati solo alla fine.
A14: Chat 2 | B14: [CH-DRE-C2] Dream Team: Manda foto fatte con l'IA; chiede foto | F14: - | K14: DIVERGENZA FORTE: Biscotto Sì, Dream Team No (pur annotando foto fatte con l'IA e richiesta di foto), Tontony 'non sappiamo', 2 squadre non rispondono. Chat su cui manca un criterio condiviso.
A15: Chat 3 | B15: [CH-TON-C3] Tontony: Ha degli elementi genuini e anche un po' tossici. Il cercare il confronto frontale fa pensare a un sì però [CH-DIV-C3] Divo: "Sembra un account" (profilo costruito/falso) | F15: [OSS-07] Si fanno troppa confidenza senza conoscersi ("non ti tratterei mai così"); insistenza nella richiesta della foto [OSS-08] Notano la foto finta inviata nella chat e quindi i metodi per guadagnare fiducia [OSS-09] Notano gli orari dei messaggi come possibile indicatore di sospetto | K15: COMUNE: troppa confidenza senza conoscersi, insistenza sulla foto, foto finta usata per guadagnare fiducia, orari sospetti. DIVERGENZA: Tontony vede 'elementi genuini' (la proposta di vedersi di persona sembra una garanzia); Dream Team la giudica non sospetta.
A16: Chat 4 (parte 1 e 2) | B16: [CH-TON-C4] Tontony: Spostarsi su Snapchat; frase di lusinga esagerata ("unica...", lettura incerta); poi chiede di non presentarsi con altri [CH-DRE-C4] Dream Team: Un po' pervertito; cerca di isolarti ("cerca la solitudine"); una foto finta; chiede dati personali; stalker; passaggio di app sospetto | F16: [OSS-10] Pressa troppo soprattutto nella fase finale ("Alle 4 in Duomo..."), però "se lo conosco da un po' ci può stare" [OSS-11] Mancano riferimenti: nessuno chiede ulteriori prove a lui, accettano passivamente il suo comportamento [OSS-12] Stalker: sa cose che non sono state dette; scrive nonostante la differenza di età [OSS-13] Passaggio a Snapchat; tono aggressivo; chiede di venire da sola e di mentire ai genitori [OSS-14] Chiede dati personali e dettagli che i ragazzi non se la sentono di condividere; mettono in discussione il passaggio a Snapchat [OSS-15] Se non lo conoscono non danno il numero o altri dettagli, per non essere tracciati/seguiti su altre piattaforme [OSS-16] Per le ragazze è strano che un ragazzo di 21 anni scriva a una ragazza di 16: chat sospetta [OSS-17] La foto sembra falsa, quindi non si fiderebbero a continuare la conversazione | K16: COMUNE: la chat più riconosciuta: cambio di app (Snapchat), richiesta di venire da sola e mentire ai genitori, differenza d'età, dati personali, sa cose non dette. SORPRESA: 'se lo conosco da un po' ci può stare' e nessuno chiede prove della sua identità (OSS-10, OSS-11).
A17: Chat 5 | B17: [CH-TON-C5] Tontony: Contraddizione nel "dove ti ho visto". Dopo aver condiviso la foto, l'adescatore non risponde più [CH-DRE-C5] Dream Team: Stalker, pervertito | F17: [OSS-18] I genitori vengono "saltati": vanno alla polizia postale o avvisano loro gli amici che le foto sono fake, mai dai genitori (poca confidenza o timore) [OSS-19] Interlocutore vago, omette informazioni, insistente, fa molte domande [OSS-20] La vittima non vuole dirlo a nessuno (comprensibile) ma bisogna parlarne: prima con persone di confidenza (sorella, amica), poi con i genitori, per sentire più pareri [OSS-21] Alcuni andrebbero avanti per capire di più su Luca; altri notano la contraddizione (dice di aver visto Matteo alla partita ma gli chiede una foto con la maglia) [OSS-22] Non avrebbero inviato la foto; in caso di sospetto lo direbbero ai genitori | K17: COMUNE: nessuno manderebbe la foto; notano la contraddizione 'ti ho visto alla partita'. DIVERGENZA: a chi chiederebbero aiuto: polizia postale e amici saltando i genitori (OSS-18), prima sorella/amica e poi genitori (OSS-20), direttamente i genitori (OSS-22). Alcuni andrebbero avanti per curiosità (OSS-21).
A18: Chat 5.1 | B18: [CH-DRE-C5.1] Dream Team: Cyberbullismo modificando foto | F18: [OSS-23] La foto modificata inoltrata nel gruppo è vista come uno scherzo; se girasse in più gruppi o con sconosciuti la prenderebbero più seriamente. Sensibilità parziale: va chiarito quando diventa grave [OSS-24] Non si mandano foto modificate con l'IA sul gruppo, la prenderebbero male indipendentemente dal tono; dipende dal soggetto preso di mira, ma se la prende male è giusto eliminarla [OSS-25] Considerano la chat uno scherzo nonostante Matteo sia uscito dal gruppo e abbia chiesto di togliere la foto | K18: DIVERGENZA: per alcuni la foto modificata nel gruppo è uno scherzo anche quando la vittima esce dal gruppo (OSS-25); per altri non si fa mai (OSS-24). Biscotto la prenderebbe sul serio solo se girasse fuori dal gruppo (OSS-23).
A19: Chat 6 | B19: [CH-DRE-C6] Dream Team: Parlare con un adulto o con qualcuno che ti possa aiutare | F19: - | K19: Nessuna squadra ha segnato la risposta preferita di Giulia. Dream Team scrive che bisogna parlare con un adulto o con qualcuno che può aiutare.

Sheet Tavola rotonda
A1: Tavola rotonda - risposte alle domande TR1-TR4
A4: Domanda | B4: Sotto-domanda (co-design) | C4: Tontony | D4: Divo | E4: Biscotto | F4: Team Pasqua | G4: Dream Team | H4: Punti comuni | I4: Divergenze | J4: Bisogni
A5: TR1. Quando vi scrive qualcuno che non conoscete, su cosa vi basate per decidere se fidarvi? | B5: Vi piacerebbe che un servizio vi insegnasse come riconoscere i segnali più affidabili da chi vi scrive? In che forma? (consigli brevi, esempi, video, giochi interattivi, botta e risposta) | C5: Questo progetto ci ha interessato perché ci ha fatto agire in prima persona, con giochi e quiz interattivi. Ci piacerebbe la presenza di un servizio educativo al comportamento online. | D5: Rispondo ma faccio sia domande sia risposte "basilari", cose di poco conto. Se ci rendiamo conto che c'è un pericolo smettiamo. Guardiamo anche gli amici in comune e le storie in evidenza (se ci sono). Sì, ci piacerebbe, magari attraverso ore scolastiche più interattive come oggi o cose più tecnologiche, non una lezione come le solite. | E5: In base ai messaggi che manda e al fatto se è insistente o meno. Incontri come oggi possono servire e sono belli. | F5: Mi fido di più se ci sono degli amici in comune e se l'ho visto almeno una volta in giro o a scuola. Inoltre ci piacerebbe avere un servizio per essere più consapevoli. | G5: Se lo conosco già dal vivo mi fido, altrimenti no. | H5: Ci si fida di chi si conosce dal vivo o di chi ha amici in comune / storie in evidenza; insistenza come campanello. Tutte le squadre che rispondono alla sotto-domanda vogliono un servizio educativo, purché attivo e interattivo ('come oggi', giochi e quiz). | I5: Strategie diverse: Dream Team non si fida mai di chi non conosce dal vivo; Divo risponde 'con cose basilari' e smette solo se avverte il pericolo (mette alla prova la conversazione invece di chiudere). | J5: B1, B3, B6
A6: TR2. Vi sentite capaci di riconoscere una foto fatta con l'IA? Cosa vi rende sicuri? | B6: Preferite ricevere feedback dalla piattaforma o vi stimola di più un gioco tipo vero o falso, con punti, livelli e sfide anche con amici online? | C6: Ci sentiamo abbastanza sicuri, anche se davanti al livello difficile del quiz ci siamo resi conto di quanto può essere facile essere adescati online. | D6: Abbastanza, soprattutto rispetto a certi adulti. Siamo più abituati a stare in contatto con l'IA. | E6: Sì, nella maggior parte dei casi, ma alcune ingannano. Guardare i dettagli. | F6: Riconosciamo la maggior parte delle foto fatte con l'IA, eccetto alcune. | G6: No, [la percezione sui volti è difficile - lettura incerta]. Gioco con punti e livelli online con gli amici. | H6: Si sentono 'abbastanza' capaci, ma ammettono che alcune foto ingannano; la sicurezza viene dal 'guardare i dettagli'. | I6: Divo si sente più capace degli adulti 'perché più abituati all'IA'; Dream Team risponde 'No' e indica il gioco a punti e livelli con amici; Tontony dice che il livello difficile ha fatto capire quanto è facile cadere. | J6: B4, B1
A7: TR3. Siete d'accordo nell'avere un forum come spazio condiviso? | B7: Deve esserci solo pubblicazione e lettura delle esperienze, o anche reazioni e commenti (revisionati per evitare commenti inappropriati)? | C7: Sì, siamo d'accordo perché l'esperienza del singolo può aiutare il gruppo, ma altre persone possono screditare queste esperienze utili. | D7: Sì, sarebbe un'ottima opzione; dovrebbero esserci più possibilità sociali (reazioni/commenti). | E7: Se ci sono consigli ed esperienze sì, ma non condivideremmo esperienze personali. | F7: Noi manterremmo le interazioni e i commenti, soprattutto se le piattaforme online incrementassero la sicurezza e controllassero i commenti negativi. | G7: Non saprei come risponderei, dato che non ho mai fatto un'esperienza in un forum. | H7: Il forum piace come luogo per leggere esperienze e consigli. | I7: Sulla scrittura: Biscotto non condividerebbe esperienze personali; Team Pasqua e Divo vogliono commenti e reazioni ma moderati; Tontony teme che altri 'screditino' le esperienze; Dream Team non ha mai usato un forum. | J7: B2
A8: TR4. Quali sono i principali motivi per cui diffidate nel parlarne con gli adulti? | B8: È utile inserire nell'app la possibilità di fare da tutor su questa problematica? Può aumentare la probabilità di parlarne o resta la paura? | C8: A quest'età si tende ad apprendere il mondo a modo proprio, senza chiedere consiglio a nessuno. Questa pratica può avere un risvolto negativo quando si nascondono fatti gravi. | D8: Perché spesso reagiscono senza cercare un punto d'incontro o di capire cosa proviamo e in che società ormai viviamo. Il tutor sarebbe utilissimo. | E8: Dover affrontare le conseguenze, essere giudicata e non avere più la libertà di prima. | F8: Ci affidiamo agli adulti perché riconosciamo in loro maggiore stabilità e maturità. Non siamo d'accordo sul tutor online perché è meglio confidarsi con qualcuno che conosci, di cui ti fidi e che può darti consigli migliori conoscendo il tuo carattere. | G8: La convinzione di poter risolvere tutto da soli e il disagio, dato che è molto difficile una conversazione. Secondo noi [il tutor] può aiutare i genitori a intervenire in questo frangente [lettura incerta]. | H8: Tutte le squadre descrivono una difficoltà a parlarne con gli adulti: paura delle conseguenze, del giudizio, di perdere libertà; adulti che reagiscono senza capire; la convinzione di farcela da soli. | I8: Sul tutor: Divo lo trova utilissimo; Team Pasqua contraria (meglio qualcuno che ti conosce) e, unica, dice di affidarsi agli adulti; Dream Team lo vede come ponte verso i genitori. | J8: B7, B5

Sheet Appunti osservazione
A1: Appunti di osservazione del team, codificati
A4: Codice | B4: Chat / momento | C4: Squadra (se nota) | D4: Appunto | E4: Tema
A5: OSS-01 | B5: Chat 1 | D5: Chat percepita come normale, forse "pressa un po' troppo" | E5: Riconoscimento segnali
A6: OSS-02 | B6: Chat 1 | D6: Notano la schermata centrale: controllare il telefono e inventare scuse | E6: Riconoscimento segnali
A7: OSS-03 | B7: Chat 1 | D7: Lo bloccherebbero | E7: Reazione
A8: OSS-04 | B8: Chat 1 | D8: L'ultima schermata, gli ultimi messaggi sono i peggiori (escalation) | E8: Riconoscimento segnali
A9: OSS-05 | B9: Chat 1 | D9: Molti capiscono che la chat 1 è pericolosa e discutono sia dei messaggi sia delle risposte | E9: Riconoscimento segnali
A10: OSS-06 | B10: Generale | D10: Molti sono diffidenti verso sconosciuti che fanno richieste esplicite, altri accettano richieste da sconosciuti | E10: Criteri di fiducia
A11: OSS-07 | B11: Chat 3 | D11: Si fanno troppa confidenza senza conoscersi ("non ti tratterei mai così"); insistenza nella richiesta della foto | E11: Riconoscimento segnali
A12: OSS-08 | B12: Chat 3 | D12: Notano la foto finta inviata nella chat e quindi i metodi per guadagnare fiducia | E12: Deepfake nelle chat
A13: OSS-09 | B13: Chat 3 | D13: Notano gli orari dei messaggi come possibile indicatore di sospetto | E13: Riconoscimento segnali
A14: OSS-10 | B14: Chat 4.1-4.2 | D14: Pressa troppo soprattutto nella fase finale ("Alle 4 in Duomo..."), però "se lo conosco da un po' ci può stare" | E14: Criteri di fiducia
A15: OSS-11 | B15: Chat 4.1-4.2 | D15: Mancano riferimenti: nessuno chiede ulteriori prove a lui, accettano passivamente il suo comportamento | E15: Verifica identità
A16: OSS-12 | B16: Chat 4.1 | D16: Stalker: sa cose che non sono state dette; scrive nonostante la differenza di età | E16: Riconoscimento segnali
... A18: OSS-14 | B18: Chat 4 | D18: Chiede dati personali e dettagli che i ragazzi non se la sentono di condividere; mettono in discussione il passaggio a Snapchat | E18: Riconoscimento segnali
A19: OSS-15 | B19: Chat 4 | C19: BIS o PAS | D19: Se non lo conoscono non danno il numero o altri dettagli, per non essere tracciati/seguiti su altre piattaforme | E19: Protezione dati
A20: OSS-16 | B20: Chat 4.1-4.2 | D20: Per le ragazze è strano che un ragazzo di 21 anni scriva a una ragazza di 16: chat sospetta | E20: Riconoscimento segnali
A21: OSS-17 | B21: Chat 4.1-4.2 | D21: La foto sembra falsa, quindi non si fiderebbero a continuare la conversazione | E21: Deepfake nelle chat
A22: OSS-18 | B22: Chat 5 | D22: I genitori vengono "saltati": vanno alla polizia postale o avvisano loro gli amici che le foto sono fake, mai dai genitori (poca confidenza o timore) | E22: Rapporto con gli adulti
A23: OSS-19 | B23: Chat 5 | D23: Interlocutore vago, omette informazioni, insistente, fa molte domande | E23: Riconoscimento segnali
A24: OSS-20 | B24: Chat 5 | D24: La vittima non vuole dirlo a nessuno (comprensibile) ma bisogna parlarne: prima con persone di confidenza (sorella, amica), poi con i genitori, per sentire più pareri | E24: Rapporto con gli adulti
A25: OSS-21 | B25: Chat 5 | D25: Alcuni andrebbero avanti per capire di più su Luca; altri notano la contraddizione (dice di aver visto Matteo alla partita ma gli chiede una foto con la maglia) | E25: Riconoscimento segnali
A26: OSS-22 | B26: Chat 5 | D26: Non avrebbero inviato la foto; in caso di sospetto lo direbbero ai genitori | E26: Rapporto con gli adulti
